2024-05-06 14:13:38,262 - apscheduler.scheduler - INFO - Scheduler started
2024-05-06 14:14:30,263 - telegram.ext.updater - INFO - Received signal 2 (SIGINT), stopping...
2024-05-06 14:14:30,263 - apscheduler.scheduler - INFO - Scheduler has been shut down
2024-05-06 14:14:46,641 - apscheduler.scheduler - INFO - Scheduler started
2024-05-06 14:14:57,425 - telegram.ext.updater - INFO - Received signal 2 (SIGINT), stopping...
2024-05-06 14:14:57,425 - apscheduler.scheduler - INFO - Scheduler has been shut down
2024-05-06 14:27:01,046 - apscheduler.scheduler - INFO - Scheduler started
2024-05-06 14:36:53,213 - telegram.ext.updater - INFO - Received signal 2 (SIGINT), stopping...
2024-05-06 14:36:53,214 - apscheduler.scheduler - INFO - Scheduler has been shut down
2024-05-06 14:49:06,562 - apscheduler.scheduler - INFO - Scheduler started
2024-05-06 14:50:45,755 - telegram.ext.updater - INFO - Received signal 2 (SIGINT), stopping...
2024-05-06 14:50:45,755 - apscheduler.scheduler - INFO - Scheduler has been shut down
2024-05-06 14:50:48,067 - apscheduler.scheduler - INFO - Scheduler started
2024-05-06 14:52:12,358 - telegram.ext.dispatcher - ERROR - No error handlers are registered, logging exception.
Traceback (most recent call last):
  File "D:\1_PT_START_2024.1\5_module\1 занятие\practice\venv\lib\site-packages\telegram\ext\dispatcher.py", line 555, in process_update
    handler.handle_update(update, self, check, context)
  File "D:\1_PT_START_2024.1\5_module\1 занятие\practice\venv\lib\site-packages\telegram\ext\conversationhandler.py", line 626, in handle_update
    new_state = handler.handle_update(update, dispatcher, check_result, context)
  File "D:\1_PT_START_2024.1\5_module\1 занятие\practice\venv\lib\site-packages\telegram\ext\handler.py", line 198, in handle_update
    return self.callback(update, context)
  File "D:\1_PT_START_2024.1\5_module\1 занятие\practice\main.py", line 36, in findEmailsCommand
    update.message.reply_text('Введите текст для поиска email')
AttributeError: 'NoneType' object has no attribute 'reply_text'
2024-05-06 14:55:39,396 - telegram.ext.dispatcher - ERROR - No error handlers are registered, logging exception.
Traceback (most recent call last):
  File "D:\1_PT_START_2024.1\5_module\1 занятие\practice\venv\lib\site-packages\telegram\ext\dispatcher.py", line 555, in process_update
    handler.handle_update(update, self, check, context)
  File "D:\1_PT_START_2024.1\5_module\1 занятие\practice\venv\lib\site-packages\telegram\ext\conversationhandler.py", line 626, in handle_update
    new_state = handler.handle_update(update, dispatcher, check_result, context)
  File "D:\1_PT_START_2024.1\5_module\1 занятие\practice\venv\lib\site-packages\telegram\ext\handler.py", line 198, in handle_update
    return self.callback(update, context)
  File "D:\1_PT_START_2024.1\5_module\1 занятие\practice\main.py", line 31, in findPhoneNumbersCommand
    update.message.reply_text('Введите текст для поиска телефонных номеров: ')
AttributeError: 'NoneType' object has no attribute 'reply_text'
2024-05-06 14:56:05,647 - telegram.ext.updater - INFO - Received signal 2 (SIGINT), stopping...
2024-05-06 14:56:05,647 - apscheduler.scheduler - INFO - Scheduler has been shut down
2024-05-06 15:00:49,874 - apscheduler.scheduler - INFO - Scheduler started
2024-05-06 15:45:29,846 - telegram.ext.updater - INFO - Received signal 2 (SIGINT), stopping...
2024-05-06 15:45:29,847 - apscheduler.scheduler - INFO - Scheduler has been shut down
2024-05-06 16:21:09,836 - apscheduler.scheduler - INFO - Scheduler started
2024-05-06 16:28:47,882 - telegram.ext.updater - INFO - Received signal 2 (SIGINT), stopping...
2024-05-06 16:28:47,882 - apscheduler.scheduler - INFO - Scheduler has been shut down
2024-05-06 16:28:50,407 - apscheduler.scheduler - INFO - Scheduler started
2024-05-06 16:33:07,745 - telegram.ext.updater - INFO - Received signal 2 (SIGINT), stopping...
2024-05-06 16:33:07,746 - apscheduler.scheduler - INFO - Scheduler has been shut down
2024-05-06 16:33:32,160 - apscheduler.scheduler - INFO - Scheduler started
2024-05-06 16:36:15,047 - telegram.ext.updater - INFO - Received signal 2 (SIGINT), stopping...
2024-05-06 16:36:15,047 - apscheduler.scheduler - INFO - Scheduler has been shut down
2024-05-06 16:54:46,321 - apscheduler.scheduler - INFO - Scheduler started
2024-05-06 16:55:10,145 - telegram.ext.dispatcher - ERROR - No error handlers are registered, logging exception.
Traceback (most recent call last):
  File "D:\1_PT_START_2024.1\5_module\1 занятие\practice\venv\lib\site-packages\telegram\ext\dispatcher.py", line 555, in process_update
    handler.handle_update(update, self, check, context)
  File "D:\1_PT_START_2024.1\5_module\1 занятие\practice\venv\lib\site-packages\telegram\ext\handler.py", line 198, in handle_update
    return self.callback(update, context)
  File "D:\1_PT_START_2024.1\5_module\1 занятие\practice\monitoring.py", line 23, in get_release
    response = execute_ssh_command(host, port, username, password, "cat /etc/*-release")
  File "D:\1_PT_START_2024.1\5_module\1 занятие\practice\monitoring.py", line 15, in execute_ssh_command
    client.connect(hostname=host, port=port, username=username, password=password)
  File "D:\1_PT_START_2024.1\5_module\1 занятие\practice\venv\lib\site-packages\paramiko\client.py", line 386, in connect
    sock.connect(addr)
PermissionError: [WinError 10013] Сделана попытка доступа к сокету методом, запрещенным правами доступа
2024-05-06 16:56:53,284 - telegram.ext.updater - INFO - Received signal 2 (SIGINT), stopping...
2024-05-06 16:56:53,284 - apscheduler.scheduler - INFO - Scheduler has been shut down
2024-05-06 16:56:56,304 - apscheduler.scheduler - INFO - Scheduler started
2024-05-06 16:56:59,360 - telegram.ext.dispatcher - ERROR - No error handlers are registered, logging exception.
Traceback (most recent call last):
  File "D:\1_PT_START_2024.1\5_module\1 занятие\practice\venv\lib\site-packages\telegram\ext\dispatcher.py", line 555, in process_update
    handler.handle_update(update, self, check, context)
  File "D:\1_PT_START_2024.1\5_module\1 занятие\practice\venv\lib\site-packages\telegram\ext\handler.py", line 198, in handle_update
    return self.callback(update, context)
  File "D:\1_PT_START_2024.1\5_module\1 занятие\practice\monitoring.py", line 23, in get_release
    response = execute_ssh_command(host, port, username, password, "cat /etc/*-release")
  File "D:\1_PT_START_2024.1\5_module\1 занятие\practice\monitoring.py", line 15, in execute_ssh_command
    client.connect(hostname=host, port=port, username=username, password=password)
  File "D:\1_PT_START_2024.1\5_module\1 занятие\practice\venv\lib\site-packages\paramiko\client.py", line 386, in connect
    sock.connect(addr)
PermissionError: [WinError 10013] Сделана попытка доступа к сокету методом, запрещенным правами доступа
2024-05-06 16:57:36,068 - telegram.ext.dispatcher - ERROR - No error handlers are registered, logging exception.
Traceback (most recent call last):
  File "D:\1_PT_START_2024.1\5_module\1 занятие\practice\venv\lib\site-packages\telegram\ext\dispatcher.py", line 555, in process_update
    handler.handle_update(update, self, check, context)
  File "D:\1_PT_START_2024.1\5_module\1 занятие\practice\venv\lib\site-packages\telegram\ext\handler.py", line 198, in handle_update
    return self.callback(update, context)
  File "D:\1_PT_START_2024.1\5_module\1 занятие\practice\monitoring.py", line 27, in get_uname
    response = execute_ssh_command(host, port, username, password, "uname -a")
  File "D:\1_PT_START_2024.1\5_module\1 занятие\practice\monitoring.py", line 15, in execute_ssh_command
    client.connect(hostname=host, port=port, username=username, password=password)
  File "D:\1_PT_START_2024.1\5_module\1 занятие\practice\venv\lib\site-packages\paramiko\client.py", line 386, in connect
    sock.connect(addr)
PermissionError: [WinError 10013] Сделана попытка доступа к сокету методом, запрещенным правами доступа
2024-05-06 16:57:58,149 - telegram.ext.updater - INFO - Received signal 2 (SIGINT), stopping...
2024-05-06 16:57:58,149 - apscheduler.scheduler - INFO - Scheduler has been shut down
2024-05-06 16:59:03,411 - apscheduler.scheduler - INFO - Scheduler started
2024-05-06 16:59:06,760 - telegram.ext.updater - INFO - Received signal 2 (SIGINT), stopping...
2024-05-06 16:59:06,760 - apscheduler.scheduler - INFO - Scheduler has been shut down
2024-05-06 16:59:12,585 - apscheduler.scheduler - INFO - Scheduler started
2024-05-06 16:59:15,953 - telegram.ext.dispatcher - ERROR - No error handlers are registered, logging exception.
Traceback (most recent call last):
  File "D:\1_PT_START_2024.1\5_module\1 занятие\practice\venv\lib\site-packages\telegram\ext\dispatcher.py", line 555, in process_update
    handler.handle_update(update, self, check, context)
  File "D:\1_PT_START_2024.1\5_module\1 занятие\practice\venv\lib\site-packages\telegram\ext\handler.py", line 198, in handle_update
    return self.callback(update, context)
  File "D:\1_PT_START_2024.1\5_module\1 занятие\practice\monitoring.py", line 34, in get_whoami
    response = execute_ssh_command(host, port, username, password, "whoami")
  File "D:\1_PT_START_2024.1\5_module\1 занятие\practice\monitoring.py", line 14, in execute_ssh_command
    client.connect(hostname=host, port=port, username=username, password=password)
  File "D:\1_PT_START_2024.1\5_module\1 занятие\practice\venv\lib\site-packages\paramiko\client.py", line 386, in connect
    sock.connect(addr)
PermissionError: [WinError 10013] Сделана попытка доступа к сокету методом, запрещенным правами доступа
2024-05-06 16:59:28,897 - telegram.ext.updater - INFO - Received signal 2 (SIGINT), stopping...
2024-05-06 16:59:28,897 - apscheduler.scheduler - INFO - Scheduler has been shut down
2024-05-06 17:23:31,318 - apscheduler.scheduler - INFO - Scheduler started
2024-05-06 17:23:37,133 - telegram.ext.updater - INFO - Received signal 2 (SIGINT), stopping...
2024-05-06 17:23:37,133 - apscheduler.scheduler - INFO - Scheduler has been shut down
2024-05-06 17:24:19,245 - apscheduler.scheduler - INFO - Scheduler started
2024-05-06 17:24:29,919 - paramiko.transport - INFO - Connected (version 2.0, client OpenSSH_9.6p1)
2024-05-06 17:24:30,050 - paramiko.transport - INFO - Authentication (publickey) failed.
2024-05-06 17:24:30,058 - paramiko.transport - INFO - Authentication (publickey) failed.
2024-05-06 17:24:30,166 - paramiko.transport - INFO - Authentication (password) successful!
2024-05-06 17:24:32,257 - paramiko.transport - INFO - Connected (version 2.0, client OpenSSH_9.6p1)
2024-05-06 17:24:32,384 - paramiko.transport - INFO - Authentication (publickey) failed.
2024-05-06 17:24:32,393 - paramiko.transport - INFO - Authentication (publickey) failed.
2024-05-06 17:24:32,447 - paramiko.transport - INFO - Authentication (password) successful!
2024-05-06 17:24:35,869 - paramiko.transport - INFO - Connected (version 2.0, client OpenSSH_9.6p1)
2024-05-06 17:24:35,996 - paramiko.transport - INFO - Authentication (publickey) failed.
2024-05-06 17:24:36,004 - paramiko.transport - INFO - Authentication (publickey) failed.
2024-05-06 17:24:36,059 - paramiko.transport - INFO - Authentication (password) successful!
2024-05-06 17:26:15,290 - telegram.ext.updater - ERROR - Error while getting Updates: urllib3 HTTPError ('Connection aborted.', ConnectionResetError(10054, 'Удаленный хост принудительно разорвал существующее подключение', None, 10054, None))
2024-05-06 17:26:15,290 - telegram.ext.dispatcher - ERROR - No error handlers are registered, logging exception.
Traceback (most recent call last):
  File "D:\1_PT_START_2024.1\5_module\1 занятие\practice\venv\lib\site-packages\telegram\vendor\ptb_urllib3\urllib3\connectionpool.py", line 614, in urlopen
    httplib_response = self._make_request(conn, method, url,
  File "D:\1_PT_START_2024.1\5_module\1 занятие\practice\venv\lib\site-packages\telegram\vendor\ptb_urllib3\urllib3\connectionpool.py", line 402, in _make_request
    six.raise_from(e, None)
  File "<string>", line 2, in raise_from
  File "D:\1_PT_START_2024.1\5_module\1 занятие\practice\venv\lib\site-packages\telegram\vendor\ptb_urllib3\urllib3\connectionpool.py", line 398, in _make_request
    httplib_response = conn.getresponse()
  File "C:\Program Files\Python39\lib\http\client.py", line 1377, in getresponse
    response.begin()
  File "C:\Program Files\Python39\lib\http\client.py", line 320, in begin
    version, status, reason = self._read_status()
  File "C:\Program Files\Python39\lib\http\client.py", line 281, in _read_status
    line = str(self.fp.readline(_MAXLINE + 1), "iso-8859-1")
  File "C:\Program Files\Python39\lib\socket.py", line 704, in readinto
    return self._sock.recv_into(b)
  File "C:\Program Files\Python39\lib\ssl.py", line 1242, in recv_into
    return self.read(nbytes, buffer)
  File "C:\Program Files\Python39\lib\ssl.py", line 1100, in read
    return self._sslobj.read(len, buffer)
ConnectionResetError: [WinError 10054] Удаленный хост принудительно разорвал существующее подключение

During handling of the above exception, another exception occurred:

Traceback (most recent call last):
  File "D:\1_PT_START_2024.1\5_module\1 занятие\practice\venv\lib\site-packages\telegram\utils\request.py", line 259, in _request_wrapper
    resp = self._con_pool.request(*args, **kwargs)
  File "D:\1_PT_START_2024.1\5_module\1 занятие\practice\venv\lib\site-packages\telegram\vendor\ptb_urllib3\urllib3\request.py", line 68, in request
    return self.request_encode_body(method, url, fields=fields,
  File "D:\1_PT_START_2024.1\5_module\1 занятие\practice\venv\lib\site-packages\telegram\vendor\ptb_urllib3\urllib3\request.py", line 148, in request_encode_body
    return self.urlopen(method, url, **extra_kw)
  File "D:\1_PT_START_2024.1\5_module\1 занятие\practice\venv\lib\site-packages\telegram\vendor\ptb_urllib3\urllib3\poolmanager.py", line 244, in urlopen
    response = conn.urlopen(method, u.request_uri, **kw)
  File "D:\1_PT_START_2024.1\5_module\1 занятие\practice\venv\lib\site-packages\telegram\vendor\ptb_urllib3\urllib3\connectionpool.py", line 665, in urlopen
    retries = retries.increment(method, url, error=e, _pool=self,
  File "D:\1_PT_START_2024.1\5_module\1 занятие\practice\venv\lib\site-packages\telegram\vendor\ptb_urllib3\urllib3\util\retry.py", line 347, in increment
    raise six.reraise(type(error), error, _stacktrace)
  File "D:\1_PT_START_2024.1\5_module\1 занятие\practice\venv\lib\site-packages\telegram\vendor\ptb_urllib3\urllib3\packages\six.py", line 685, in reraise
    raise value.with_traceback(tb)
  File "D:\1_PT_START_2024.1\5_module\1 занятие\practice\venv\lib\site-packages\telegram\vendor\ptb_urllib3\urllib3\connectionpool.py", line 614, in urlopen
    httplib_response = self._make_request(conn, method, url,
  File "D:\1_PT_START_2024.1\5_module\1 занятие\practice\venv\lib\site-packages\telegram\vendor\ptb_urllib3\urllib3\connectionpool.py", line 402, in _make_request
    six.raise_from(e, None)
  File "<string>", line 2, in raise_from
  File "D:\1_PT_START_2024.1\5_module\1 занятие\practice\venv\lib\site-packages\telegram\vendor\ptb_urllib3\urllib3\connectionpool.py", line 398, in _make_request
    httplib_response = conn.getresponse()
  File "C:\Program Files\Python39\lib\http\client.py", line 1377, in getresponse
    response.begin()
  File "C:\Program Files\Python39\lib\http\client.py", line 320, in begin
    version, status, reason = self._read_status()
  File "C:\Program Files\Python39\lib\http\client.py", line 281, in _read_status
    line = str(self.fp.readline(_MAXLINE + 1), "iso-8859-1")
  File "C:\Program Files\Python39\lib\socket.py", line 704, in readinto
    return self._sock.recv_into(b)
  File "C:\Program Files\Python39\lib\ssl.py", line 1242, in recv_into
    return self.read(nbytes, buffer)
  File "C:\Program Files\Python39\lib\ssl.py", line 1100, in read
    return self._sslobj.read(len, buffer)
telegram.vendor.ptb_urllib3.urllib3.exceptions.ProtocolError: ('Connection aborted.', ConnectionResetError(10054, 'Удаленный хост принудительно разорвал существующее подключение', None, 10054, None))

The above exception was the direct cause of the following exception:

Traceback (most recent call last):
  File "D:\1_PT_START_2024.1\5_module\1 занятие\practice\venv\lib\site-packages\telegram\ext\updater.py", line 646, in _network_loop_retry
    if not action_cb():
  File "D:\1_PT_START_2024.1\5_module\1 занятие\practice\venv\lib\site-packages\telegram\ext\updater.py", line 597, in polling_action_cb
    updates = self.bot.get_updates(
  File "D:\1_PT_START_2024.1\5_module\1 занятие\practice\venv\lib\site-packages\telegram\ext\extbot.py", line 222, in get_updates
    updates = super().get_updates(
  File "D:\1_PT_START_2024.1\5_module\1 занятие\practice\venv\lib\site-packages\telegram\bot.py", line 130, in decorator
    result = func(*args, **kwargs)
  File "D:\1_PT_START_2024.1\5_module\1 занятие\practice\venv\lib\site-packages\telegram\bot.py", line 2861, in get_updates
    self._post(
  File "D:\1_PT_START_2024.1\5_module\1 занятие\practice\venv\lib\site-packages\telegram\bot.py", line 295, in _post
    return self.request.post(
  File "D:\1_PT_START_2024.1\5_module\1 занятие\practice\venv\lib\site-packages\telegram\utils\request.py", line 356, in post
    result = self._request_wrapper(
  File "D:\1_PT_START_2024.1\5_module\1 занятие\practice\venv\lib\site-packages\telegram\utils\request.py", line 265, in _request_wrapper
    raise NetworkError(f'urllib3 HTTPError {error}') from error
telegram.error.NetworkError: urllib3 HTTPError ('Connection aborted.', ConnectionResetError(10054, 'Удаленный хост принудительно разорвал существующее подключение', None, 10054, None))
2024-05-06 17:32:58,013 - telegram.ext.updater - INFO - Received signal 2 (SIGINT), stopping...
2024-05-06 17:32:58,013 - apscheduler.scheduler - INFO - Scheduler has been shut down
2024-05-06 17:38:30,120 - apscheduler.scheduler - INFO - Scheduler started
2024-05-06 17:38:40,789 - telegram.ext.dispatcher - ERROR - No error handlers are registered, logging exception.
Traceback (most recent call last):
  File "D:\1_PT_START_2024.1\5_module\1 занятие\practice\venv\lib\site-packages\telegram\ext\dispatcher.py", line 555, in process_update
    handler.handle_update(update, self, check, context)
  File "D:\1_PT_START_2024.1\5_module\1 занятие\practice\venv\lib\site-packages\telegram\ext\handler.py", line 198, in handle_update
    return self.callback(update, context)
  File "D:\1_PT_START_2024.1\5_module\1 занятие\practice\monitoring.py", line 24, in get_release
    response = execute_ssh_command(host, port, username, password, "cat /etc/*-release")
  File "D:\1_PT_START_2024.1\5_module\1 занятие\practice\monitoring.py", line 14, in execute_ssh_command
    client.connect(hostname=host, port=port, username=username, password=password)
  File "D:\1_PT_START_2024.1\5_module\1 занятие\practice\venv\lib\site-packages\paramiko\client.py", line 386, in connect
    sock.connect(addr)
PermissionError: [WinError 10013] Сделана попытка доступа к сокету методом, запрещенным правами доступа
2024-05-06 17:38:45,327 - telegram.ext.updater - ERROR - Error while getting Updates: urllib3 HTTPError ('Connection aborted.', ConnectionResetError(10054, 'Удаленный хост принудительно разорвал существующее подключение', None, 10054, None))
2024-05-06 17:38:45,328 - telegram.ext.dispatcher - ERROR - No error handlers are registered, logging exception.
Traceback (most recent call last):
  File "D:\1_PT_START_2024.1\5_module\1 занятие\practice\venv\lib\site-packages\telegram\vendor\ptb_urllib3\urllib3\connectionpool.py", line 614, in urlopen
    httplib_response = self._make_request(conn, method, url,
  File "D:\1_PT_START_2024.1\5_module\1 занятие\practice\venv\lib\site-packages\telegram\vendor\ptb_urllib3\urllib3\connectionpool.py", line 402, in _make_request
    six.raise_from(e, None)
  File "<string>", line 2, in raise_from
  File "D:\1_PT_START_2024.1\5_module\1 занятие\practice\venv\lib\site-packages\telegram\vendor\ptb_urllib3\urllib3\connectionpool.py", line 398, in _make_request
    httplib_response = conn.getresponse()
  File "C:\Program Files\Python39\lib\http\client.py", line 1377, in getresponse
    response.begin()
  File "C:\Program Files\Python39\lib\http\client.py", line 320, in begin
    version, status, reason = self._read_status()
  File "C:\Program Files\Python39\lib\http\client.py", line 281, in _read_status
    line = str(self.fp.readline(_MAXLINE + 1), "iso-8859-1")
  File "C:\Program Files\Python39\lib\socket.py", line 704, in readinto
    return self._sock.recv_into(b)
  File "C:\Program Files\Python39\lib\ssl.py", line 1242, in recv_into
    return self.read(nbytes, buffer)
  File "C:\Program Files\Python39\lib\ssl.py", line 1100, in read
    return self._sslobj.read(len, buffer)
ConnectionResetError: [WinError 10054] Удаленный хост принудительно разорвал существующее подключение

During handling of the above exception, another exception occurred:

Traceback (most recent call last):
  File "D:\1_PT_START_2024.1\5_module\1 занятие\practice\venv\lib\site-packages\telegram\utils\request.py", line 259, in _request_wrapper
    resp = self._con_pool.request(*args, **kwargs)
  File "D:\1_PT_START_2024.1\5_module\1 занятие\practice\venv\lib\site-packages\telegram\vendor\ptb_urllib3\urllib3\request.py", line 68, in request
    return self.request_encode_body(method, url, fields=fields,
  File "D:\1_PT_START_2024.1\5_module\1 занятие\practice\venv\lib\site-packages\telegram\vendor\ptb_urllib3\urllib3\request.py", line 148, in request_encode_body
    return self.urlopen(method, url, **extra_kw)
  File "D:\1_PT_START_2024.1\5_module\1 занятие\practice\venv\lib\site-packages\telegram\vendor\ptb_urllib3\urllib3\poolmanager.py", line 244, in urlopen
    response = conn.urlopen(method, u.request_uri, **kw)
  File "D:\1_PT_START_2024.1\5_module\1 занятие\practice\venv\lib\site-packages\telegram\vendor\ptb_urllib3\urllib3\connectionpool.py", line 665, in urlopen
    retries = retries.increment(method, url, error=e, _pool=self,
  File "D:\1_PT_START_2024.1\5_module\1 занятие\practice\venv\lib\site-packages\telegram\vendor\ptb_urllib3\urllib3\util\retry.py", line 347, in increment
    raise six.reraise(type(error), error, _stacktrace)
  File "D:\1_PT_START_2024.1\5_module\1 занятие\practice\venv\lib\site-packages\telegram\vendor\ptb_urllib3\urllib3\packages\six.py", line 685, in reraise
    raise value.with_traceback(tb)
  File "D:\1_PT_START_2024.1\5_module\1 занятие\practice\venv\lib\site-packages\telegram\vendor\ptb_urllib3\urllib3\connectionpool.py", line 614, in urlopen
    httplib_response = self._make_request(conn, method, url,
  File "D:\1_PT_START_2024.1\5_module\1 занятие\practice\venv\lib\site-packages\telegram\vendor\ptb_urllib3\urllib3\connectionpool.py", line 402, in _make_request
    six.raise_from(e, None)
  File "<string>", line 2, in raise_from
  File "D:\1_PT_START_2024.1\5_module\1 занятие\practice\venv\lib\site-packages\telegram\vendor\ptb_urllib3\urllib3\connectionpool.py", line 398, in _make_request
    httplib_response = conn.getresponse()
  File "C:\Program Files\Python39\lib\http\client.py", line 1377, in getresponse
    response.begin()
  File "C:\Program Files\Python39\lib\http\client.py", line 320, in begin
    version, status, reason = self._read_status()
  File "C:\Program Files\Python39\lib\http\client.py", line 281, in _read_status
    line = str(self.fp.readline(_MAXLINE + 1), "iso-8859-1")
  File "C:\Program Files\Python39\lib\socket.py", line 704, in readinto
    return self._sock.recv_into(b)
  File "C:\Program Files\Python39\lib\ssl.py", line 1242, in recv_into
    return self.read(nbytes, buffer)
  File "C:\Program Files\Python39\lib\ssl.py", line 1100, in read
    return self._sslobj.read(len, buffer)
telegram.vendor.ptb_urllib3.urllib3.exceptions.ProtocolError: ('Connection aborted.', ConnectionResetError(10054, 'Удаленный хост принудительно разорвал существующее подключение', None, 10054, None))

The above exception was the direct cause of the following exception:

Traceback (most recent call last):
  File "D:\1_PT_START_2024.1\5_module\1 занятие\practice\venv\lib\site-packages\telegram\ext\updater.py", line 646, in _network_loop_retry
    if not action_cb():
  File "D:\1_PT_START_2024.1\5_module\1 занятие\practice\venv\lib\site-packages\telegram\ext\updater.py", line 597, in polling_action_cb
    updates = self.bot.get_updates(
  File "D:\1_PT_START_2024.1\5_module\1 занятие\practice\venv\lib\site-packages\telegram\ext\extbot.py", line 222, in get_updates
    updates = super().get_updates(
  File "D:\1_PT_START_2024.1\5_module\1 занятие\practice\venv\lib\site-packages\telegram\bot.py", line 130, in decorator
    result = func(*args, **kwargs)
  File "D:\1_PT_START_2024.1\5_module\1 занятие\practice\venv\lib\site-packages\telegram\bot.py", line 2861, in get_updates
    self._post(
  File "D:\1_PT_START_2024.1\5_module\1 занятие\practice\venv\lib\site-packages\telegram\bot.py", line 295, in _post
    return self.request.post(
  File "D:\1_PT_START_2024.1\5_module\1 занятие\practice\venv\lib\site-packages\telegram\utils\request.py", line 356, in post
    result = self._request_wrapper(
  File "D:\1_PT_START_2024.1\5_module\1 занятие\practice\venv\lib\site-packages\telegram\utils\request.py", line 265, in _request_wrapper
    raise NetworkError(f'urllib3 HTTPError {error}') from error
telegram.error.NetworkError: urllib3 HTTPError ('Connection aborted.', ConnectionResetError(10054, 'Удаленный хост принудительно разорвал существующее подключение', None, 10054, None))
2024-05-06 17:38:54,963 - paramiko.transport - INFO - Connected (version 2.0, client OpenSSH_9.6p1)
2024-05-06 17:38:55,100 - paramiko.transport - INFO - Authentication (publickey) failed.
2024-05-06 17:38:55,112 - paramiko.transport - INFO - Authentication (publickey) failed.
2024-05-06 17:38:55,141 - paramiko.transport - INFO - Authentication (password) successful!
2024-05-06 17:39:03,266 - paramiko.transport - INFO - Connected (version 2.0, client OpenSSH_9.6p1)
2024-05-06 17:39:03,389 - paramiko.transport - INFO - Authentication (publickey) failed.
2024-05-06 17:39:03,398 - paramiko.transport - INFO - Authentication (publickey) failed.
2024-05-06 17:39:03,427 - paramiko.transport - INFO - Authentication (password) successful!
2024-05-06 17:39:03,501 - telegram.ext.dispatcher - ERROR - No error handlers are registered, logging exception.
Traceback (most recent call last):
  File "D:\1_PT_START_2024.1\5_module\1 занятие\practice\venv\lib\site-packages\telegram\ext\dispatcher.py", line 555, in process_update
    handler.handle_update(update, self, check, context)
  File "D:\1_PT_START_2024.1\5_module\1 занятие\practice\venv\lib\site-packages\telegram\ext\handler.py", line 198, in handle_update
    return self.callback(update, context)
  File "D:\1_PT_START_2024.1\5_module\1 занятие\practice\monitoring.py", line 30, in get_uname
    update.message.reply_text(response)
AttributeError: 'NoneType' object has no attribute 'reply_text'
2024-05-06 17:39:05,447 - paramiko.transport - INFO - Connected (version 2.0, client OpenSSH_9.6p1)
2024-05-06 17:39:05,575 - paramiko.transport - INFO - Authentication (publickey) failed.
2024-05-06 17:39:05,583 - paramiko.transport - INFO - Authentication (publickey) failed.
2024-05-06 17:39:05,612 - paramiko.transport - INFO - Authentication (password) successful!
2024-05-06 17:39:15,835 - paramiko.transport - INFO - Connected (version 2.0, client OpenSSH_9.6p1)
2024-05-06 17:39:15,963 - paramiko.transport - INFO - Authentication (publickey) failed.
2024-05-06 17:39:15,971 - paramiko.transport - INFO - Authentication (publickey) failed.
2024-05-06 17:39:16,000 - paramiko.transport - INFO - Authentication (password) successful!
2024-05-06 17:39:22,630 - paramiko.transport - INFO - Connected (version 2.0, client OpenSSH_9.6p1)
2024-05-06 17:39:22,754 - paramiko.transport - INFO - Authentication (publickey) failed.
2024-05-06 17:39:22,762 - paramiko.transport - INFO - Authentication (publickey) failed.
2024-05-06 17:39:22,818 - paramiko.transport - INFO - Authentication (password) successful!
2024-05-06 17:39:27,676 - paramiko.transport - INFO - Connected (version 2.0, client OpenSSH_9.6p1)
2024-05-06 17:39:27,805 - paramiko.transport - INFO - Authentication (publickey) failed.
2024-05-06 17:39:27,813 - paramiko.transport - INFO - Authentication (publickey) failed.
2024-05-06 17:39:27,868 - paramiko.transport - INFO - Authentication (password) successful!
2024-05-06 17:39:30,924 - paramiko.transport - INFO - Connected (version 2.0, client OpenSSH_9.6p1)
2024-05-06 17:39:31,046 - paramiko.transport - INFO - Authentication (publickey) failed.
2024-05-06 17:39:31,055 - paramiko.transport - INFO - Authentication (publickey) failed.
2024-05-06 17:39:31,083 - paramiko.transport - INFO - Authentication (password) successful!
2024-05-06 17:39:34,151 - paramiko.transport - INFO - Connected (version 2.0, client OpenSSH_9.6p1)
2024-05-06 17:39:34,276 - paramiko.transport - INFO - Authentication (publickey) failed.
2024-05-06 17:39:34,285 - paramiko.transport - INFO - Authentication (publickey) failed.
2024-05-06 17:39:34,313 - paramiko.transport - INFO - Authentication (password) successful!
2024-05-06 17:39:37,737 - paramiko.transport - INFO - Connected (version 2.0, client OpenSSH_9.6p1)
2024-05-06 17:39:37,864 - paramiko.transport - INFO - Authentication (publickey) failed.
2024-05-06 17:39:37,872 - paramiko.transport - INFO - Authentication (publickey) failed.
2024-05-06 17:39:37,901 - paramiko.transport - INFO - Authentication (password) successful!
2024-05-06 17:39:40,780 - paramiko.transport - INFO - Connected (version 2.0, client OpenSSH_9.6p1)
2024-05-06 17:39:40,905 - paramiko.transport - INFO - Authentication (publickey) failed.
2024-05-06 17:39:40,913 - paramiko.transport - INFO - Authentication (publickey) failed.
2024-05-06 17:39:40,941 - paramiko.transport - INFO - Authentication (password) successful!
2024-05-06 17:39:41,124 - telegram.ext.dispatcher - ERROR - No error handlers are registered, logging exception.
Traceback (most recent call last):
  File "D:\1_PT_START_2024.1\5_module\1 занятие\practice\venv\lib\site-packages\telegram\ext\dispatcher.py", line 555, in process_update
    handler.handle_update(update, self, check, context)
  File "D:\1_PT_START_2024.1\5_module\1 занятие\practice\venv\lib\site-packages\telegram\ext\handler.py", line 198, in handle_update
    return self.callback(update, context)
  File "D:\1_PT_START_2024.1\5_module\1 занятие\practice\monitoring.py", line 65, in get_critical
    update.message.reply_text(response)
  File "D:\1_PT_START_2024.1\5_module\1 занятие\practice\venv\lib\site-packages\telegram\message.py", line 764, in reply_text
    return self.bot.send_message(
  File "D:\1_PT_START_2024.1\5_module\1 занятие\practice\venv\lib\site-packages\telegram\bot.py", line 130, in decorator
    result = func(*args, **kwargs)
  File "D:\1_PT_START_2024.1\5_module\1 занятие\practice\venv\lib\site-packages\telegram\bot.py", line 513, in send_message
    return self._message(  # type: ignore[return-value]
  File "D:\1_PT_START_2024.1\5_module\1 занятие\practice\venv\lib\site-packages\telegram\ext\extbot.py", line 199, in _message
    result = super()._message(
  File "D:\1_PT_START_2024.1\5_module\1 занятие\practice\venv\lib\site-packages\telegram\bot.py", line 332, in _message
    result = self._post(endpoint, data, timeout=timeout, api_kwargs=api_kwargs)
  File "D:\1_PT_START_2024.1\5_module\1 занятие\practice\venv\lib\site-packages\telegram\bot.py", line 295, in _post
    return self.request.post(
  File "D:\1_PT_START_2024.1\5_module\1 занятие\practice\venv\lib\site-packages\telegram\utils\request.py", line 356, in post
    result = self._request_wrapper(
  File "D:\1_PT_START_2024.1\5_module\1 занятие\practice\venv\lib\site-packages\telegram\utils\request.py", line 279, in _request_wrapper
    raise BadRequest(message)
telegram.error.BadRequest: Message text is empty
2024-05-06 17:40:13,857 - paramiko.transport - INFO - Connected (version 2.0, client OpenSSH_9.6p1)
2024-05-06 17:40:13,982 - paramiko.transport - INFO - Authentication (publickey) failed.
2024-05-06 17:40:13,990 - paramiko.transport - INFO - Authentication (publickey) failed.
2024-05-06 17:40:14,019 - paramiko.transport - INFO - Authentication (password) successful!
2024-05-06 17:40:14,294 - telegram.ext.dispatcher - ERROR - No error handlers are registered, logging exception.
Traceback (most recent call last):
  File "D:\1_PT_START_2024.1\5_module\1 занятие\practice\venv\lib\site-packages\telegram\ext\dispatcher.py", line 555, in process_update
    handler.handle_update(update, self, check, context)
  File "D:\1_PT_START_2024.1\5_module\1 занятие\practice\venv\lib\site-packages\telegram\ext\handler.py", line 198, in handle_update
    return self.callback(update, context)
  File "D:\1_PT_START_2024.1\5_module\1 занятие\practice\monitoring.py", line 70, in get_ps
    update.message.reply_text(response)
  File "D:\1_PT_START_2024.1\5_module\1 занятие\practice\venv\lib\site-packages\telegram\message.py", line 764, in reply_text
    return self.bot.send_message(
  File "D:\1_PT_START_2024.1\5_module\1 занятие\practice\venv\lib\site-packages\telegram\bot.py", line 130, in decorator
    result = func(*args, **kwargs)
  File "D:\1_PT_START_2024.1\5_module\1 занятие\practice\venv\lib\site-packages\telegram\bot.py", line 513, in send_message
    return self._message(  # type: ignore[return-value]
  File "D:\1_PT_START_2024.1\5_module\1 занятие\practice\venv\lib\site-packages\telegram\ext\extbot.py", line 199, in _message
    result = super()._message(
  File "D:\1_PT_START_2024.1\5_module\1 занятие\practice\venv\lib\site-packages\telegram\bot.py", line 332, in _message
    result = self._post(endpoint, data, timeout=timeout, api_kwargs=api_kwargs)
  File "D:\1_PT_START_2024.1\5_module\1 занятие\practice\venv\lib\site-packages\telegram\bot.py", line 295, in _post
    return self.request.post(
  File "D:\1_PT_START_2024.1\5_module\1 занятие\practice\venv\lib\site-packages\telegram\utils\request.py", line 356, in post
    result = self._request_wrapper(
  File "D:\1_PT_START_2024.1\5_module\1 занятие\practice\venv\lib\site-packages\telegram\utils\request.py", line 279, in _request_wrapper
    raise BadRequest(message)
telegram.error.BadRequest: Message is too long
2024-05-06 17:41:06,388 - telegram.ext.updater - INFO - Received signal 2 (SIGINT), stopping...
2024-05-06 17:41:06,388 - apscheduler.scheduler - INFO - Scheduler has been shut down
2024-05-06 17:44:05,946 - apscheduler.scheduler - INFO - Scheduler started
2024-05-06 17:44:10,141 - paramiko.transport - INFO - Connected (version 2.0, client OpenSSH_9.6p1)
2024-05-06 17:44:10,271 - paramiko.transport - INFO - Authentication (publickey) failed.
2024-05-06 17:44:10,279 - paramiko.transport - INFO - Authentication (publickey) failed.
2024-05-06 17:44:10,307 - paramiko.transport - INFO - Authentication (password) successful!
2024-05-06 17:44:10,714 - telegram.ext.dispatcher - ERROR - No error handlers are registered, logging exception.
Traceback (most recent call last):
  File "D:\1_PT_START_2024.1\5_module\1 занятие\practice\venv\lib\site-packages\telegram\ext\dispatcher.py", line 555, in process_update
    handler.handle_update(update, self, check, context)
  File "D:\1_PT_START_2024.1\5_module\1 занятие\practice\venv\lib\site-packages\telegram\ext\handler.py", line 198, in handle_update
    return self.callback(update, context)
  File "D:\1_PT_START_2024.1\5_module\1 занятие\practice\monitoring.py", line 65, in get_critical
    update.message.reply_text(response)
  File "D:\1_PT_START_2024.1\5_module\1 занятие\practice\venv\lib\site-packages\telegram\message.py", line 764, in reply_text
    return self.bot.send_message(
  File "D:\1_PT_START_2024.1\5_module\1 занятие\practice\venv\lib\site-packages\telegram\bot.py", line 130, in decorator
    result = func(*args, **kwargs)
  File "D:\1_PT_START_2024.1\5_module\1 занятие\practice\venv\lib\site-packages\telegram\bot.py", line 513, in send_message
    return self._message(  # type: ignore[return-value]
  File "D:\1_PT_START_2024.1\5_module\1 занятие\practice\venv\lib\site-packages\telegram\ext\extbot.py", line 199, in _message
    result = super()._message(
  File "D:\1_PT_START_2024.1\5_module\1 занятие\practice\venv\lib\site-packages\telegram\bot.py", line 332, in _message
    result = self._post(endpoint, data, timeout=timeout, api_kwargs=api_kwargs)
  File "D:\1_PT_START_2024.1\5_module\1 занятие\practice\venv\lib\site-packages\telegram\bot.py", line 295, in _post
    return self.request.post(
  File "D:\1_PT_START_2024.1\5_module\1 занятие\practice\venv\lib\site-packages\telegram\utils\request.py", line 356, in post
    result = self._request_wrapper(
  File "D:\1_PT_START_2024.1\5_module\1 занятие\practice\venv\lib\site-packages\telegram\utils\request.py", line 279, in _request_wrapper
    raise BadRequest(message)
telegram.error.BadRequest: Message text is empty
2024-05-06 17:44:52,958 - paramiko.transport - INFO - Connected (version 2.0, client OpenSSH_9.6p1)
2024-05-06 17:44:53,087 - paramiko.transport - INFO - Authentication (publickey) failed.
2024-05-06 17:44:53,095 - paramiko.transport - INFO - Authentication (publickey) failed.
2024-05-06 17:44:53,123 - paramiko.transport - INFO - Authentication (password) successful!
2024-05-06 17:45:53,932 - telegram.ext.updater - INFO - Received signal 2 (SIGINT), stopping...
2024-05-06 17:45:53,932 - apscheduler.scheduler - INFO - Scheduler has been shut down
2024-05-06 17:46:35,632 - apscheduler.scheduler - INFO - Scheduler started
2024-05-06 17:48:10,551 - telegram.ext.updater - INFO - Received signal 2 (SIGINT), stopping...
2024-05-06 17:48:10,551 - apscheduler.scheduler - INFO - Scheduler has been shut down
2024-05-06 17:48:13,640 - apscheduler.scheduler - INFO - Scheduler started
2024-05-06 17:48:17,261 - paramiko.transport - INFO - Connected (version 2.0, client OpenSSH_9.6p1)
2024-05-06 17:48:17,393 - paramiko.transport - INFO - Authentication (publickey) failed.
2024-05-06 17:48:17,401 - paramiko.transport - INFO - Authentication (publickey) failed.
2024-05-06 17:48:17,429 - paramiko.transport - INFO - Authentication (password) successful!
2024-05-06 17:48:20,361 - paramiko.transport - INFO - Connected (version 2.0, client OpenSSH_9.6p1)
2024-05-06 17:48:20,487 - paramiko.transport - INFO - Authentication (publickey) failed.
2024-05-06 17:48:20,495 - paramiko.transport - INFO - Authentication (publickey) failed.
2024-05-06 17:48:20,523 - paramiko.transport - INFO - Authentication (password) successful!
2024-05-06 17:49:17,153 - paramiko.transport - INFO - Connected (version 2.0, client OpenSSH_9.6p1)
2024-05-06 17:49:17,278 - paramiko.transport - INFO - Authentication (publickey) failed.
2024-05-06 17:49:17,286 - paramiko.transport - INFO - Authentication (publickey) failed.
2024-05-06 17:49:17,315 - paramiko.transport - INFO - Authentication (password) successful!
2024-05-06 17:50:09,518 - paramiko.transport - INFO - Connected (version 2.0, client OpenSSH_9.6p1)
2024-05-06 17:50:09,644 - paramiko.transport - INFO - Authentication (publickey) failed.
2024-05-06 17:50:09,653 - paramiko.transport - INFO - Authentication (publickey) failed.
2024-05-06 17:50:09,682 - paramiko.transport - INFO - Authentication (password) successful!
2024-05-06 17:50:14,513 - paramiko.transport - INFO - Connected (version 2.0, client OpenSSH_9.6p1)
2024-05-06 17:50:14,638 - paramiko.transport - INFO - Authentication (publickey) failed.
2024-05-06 17:50:14,646 - paramiko.transport - INFO - Authentication (publickey) failed.
2024-05-06 17:50:14,674 - paramiko.transport - INFO - Authentication (password) successful!
2024-05-06 17:50:15,258 - telegram.ext.dispatcher - ERROR - No error handlers are registered, logging exception.
Traceback (most recent call last):
  File "D:\1_PT_START_2024.1\5_module\1 занятие\practice\venv\lib\site-packages\telegram\ext\dispatcher.py", line 555, in process_update
    handler.handle_update(update, self, check, context)
  File "D:\1_PT_START_2024.1\5_module\1 занятие\practice\venv\lib\site-packages\telegram\ext\handler.py", line 198, in handle_update
    return self.callback(update, context)
  File "D:\1_PT_START_2024.1\5_module\1 занятие\practice\monitoring.py", line 90, in get_apt_list
    update.message.reply_text(response)
  File "D:\1_PT_START_2024.1\5_module\1 занятие\practice\venv\lib\site-packages\telegram\message.py", line 764, in reply_text
    return self.bot.send_message(
  File "D:\1_PT_START_2024.1\5_module\1 занятие\practice\venv\lib\site-packages\telegram\bot.py", line 130, in decorator
    result = func(*args, **kwargs)
  File "D:\1_PT_START_2024.1\5_module\1 занятие\practice\venv\lib\site-packages\telegram\bot.py", line 513, in send_message
    return self._message(  # type: ignore[return-value]
  File "D:\1_PT_START_2024.1\5_module\1 занятие\practice\venv\lib\site-packages\telegram\ext\extbot.py", line 199, in _message
    result = super()._message(
  File "D:\1_PT_START_2024.1\5_module\1 занятие\practice\venv\lib\site-packages\telegram\bot.py", line 332, in _message
    result = self._post(endpoint, data, timeout=timeout, api_kwargs=api_kwargs)
  File "D:\1_PT_START_2024.1\5_module\1 занятие\practice\venv\lib\site-packages\telegram\bot.py", line 295, in _post
    return self.request.post(
  File "D:\1_PT_START_2024.1\5_module\1 занятие\practice\venv\lib\site-packages\telegram\utils\request.py", line 356, in post
    result = self._request_wrapper(
  File "D:\1_PT_START_2024.1\5_module\1 занятие\practice\venv\lib\site-packages\telegram\utils\request.py", line 279, in _request_wrapper
    raise BadRequest(message)
telegram.error.BadRequest: Text is too long
2024-05-06 17:50:39,968 - telegram.ext.updater - INFO - Received signal 2 (SIGINT), stopping...
2024-05-06 17:50:39,968 - apscheduler.scheduler - INFO - Scheduler has been shut down
2024-05-06 17:51:02,129 - apscheduler.scheduler - INFO - Scheduler started
2024-05-06 17:51:06,236 - paramiko.transport - INFO - Connected (version 2.0, client OpenSSH_9.6p1)
2024-05-06 17:51:06,364 - paramiko.transport - INFO - Authentication (publickey) failed.
2024-05-06 17:51:06,373 - paramiko.transport - INFO - Authentication (publickey) failed.
2024-05-06 17:51:06,401 - paramiko.transport - INFO - Authentication (password) successful!
2024-05-06 17:51:07,302 - telegram.ext.dispatcher - ERROR - No error handlers are registered, logging exception.
Traceback (most recent call last):
  File "D:\1_PT_START_2024.1\5_module\1 занятие\practice\venv\lib\site-packages\telegram\ext\dispatcher.py", line 555, in process_update
    handler.handle_update(update, self, check, context)
  File "D:\1_PT_START_2024.1\5_module\1 занятие\practice\venv\lib\site-packages\telegram\ext\handler.py", line 198, in handle_update
    return self.callback(update, context)
  File "D:\1_PT_START_2024.1\5_module\1 занятие\practice\monitoring.py", line 90, in get_apt_list
    update.message.reply_text(response)
  File "D:\1_PT_START_2024.1\5_module\1 занятие\practice\venv\lib\site-packages\telegram\message.py", line 764, in reply_text
    return self.bot.send_message(
  File "D:\1_PT_START_2024.1\5_module\1 занятие\practice\venv\lib\site-packages\telegram\bot.py", line 130, in decorator
    result = func(*args, **kwargs)
  File "D:\1_PT_START_2024.1\5_module\1 занятие\practice\venv\lib\site-packages\telegram\bot.py", line 513, in send_message
    return self._message(  # type: ignore[return-value]
  File "D:\1_PT_START_2024.1\5_module\1 занятие\practice\venv\lib\site-packages\telegram\ext\extbot.py", line 199, in _message
    result = super()._message(
  File "D:\1_PT_START_2024.1\5_module\1 занятие\practice\venv\lib\site-packages\telegram\bot.py", line 332, in _message
    result = self._post(endpoint, data, timeout=timeout, api_kwargs=api_kwargs)
  File "D:\1_PT_START_2024.1\5_module\1 занятие\practice\venv\lib\site-packages\telegram\bot.py", line 295, in _post
    return self.request.post(
  File "D:\1_PT_START_2024.1\5_module\1 занятие\practice\venv\lib\site-packages\telegram\utils\request.py", line 356, in post
    result = self._request_wrapper(
  File "D:\1_PT_START_2024.1\5_module\1 занятие\practice\venv\lib\site-packages\telegram\utils\request.py", line 279, in _request_wrapper
    raise BadRequest(message)
telegram.error.BadRequest: Text is too long
2024-05-06 17:52:07,928 - telegram.ext.updater - INFO - Received signal 2 (SIGINT), stopping...
2024-05-06 17:52:07,928 - apscheduler.scheduler - INFO - Scheduler has been shut down
2024-05-06 17:52:11,702 - apscheduler.scheduler - INFO - Scheduler started
2024-05-06 17:52:13,610 - paramiko.transport - INFO - Connected (version 2.0, client OpenSSH_9.6p1)
2024-05-06 17:52:13,738 - paramiko.transport - INFO - Authentication (publickey) failed.
2024-05-06 17:52:13,746 - paramiko.transport - INFO - Authentication (publickey) failed.
2024-05-06 17:52:13,801 - paramiko.transport - INFO - Authentication (password) successful!
2024-05-06 17:52:41,258 - paramiko.transport - INFO - Connected (version 2.0, client OpenSSH_9.6p1)
2024-05-06 17:52:41,404 - paramiko.transport - INFO - Authentication (publickey) failed.
2024-05-06 17:52:41,412 - paramiko.transport - INFO - Authentication (publickey) failed.
2024-05-06 17:52:41,440 - paramiko.transport - INFO - Authentication (password) successful!
2024-05-06 17:52:41,626 - telegram.ext.dispatcher - ERROR - No error handlers are registered, logging exception.
Traceback (most recent call last):
  File "D:\1_PT_START_2024.1\5_module\1 занятие\practice\venv\lib\site-packages\telegram\ext\dispatcher.py", line 555, in process_update
    handler.handle_update(update, self, check, context)
  File "D:\1_PT_START_2024.1\5_module\1 занятие\practice\venv\lib\site-packages\telegram\ext\handler.py", line 198, in handle_update
    return self.callback(update, context)
  File "D:\1_PT_START_2024.1\5_module\1 занятие\practice\monitoring.py", line 95, in get_services
    update.message.reply_text(response)
  File "D:\1_PT_START_2024.1\5_module\1 занятие\practice\venv\lib\site-packages\telegram\message.py", line 764, in reply_text
    return self.bot.send_message(
  File "D:\1_PT_START_2024.1\5_module\1 занятие\practice\venv\lib\site-packages\telegram\bot.py", line 130, in decorator
    result = func(*args, **kwargs)
  File "D:\1_PT_START_2024.1\5_module\1 занятие\practice\venv\lib\site-packages\telegram\bot.py", line 513, in send_message
    return self._message(  # type: ignore[return-value]
  File "D:\1_PT_START_2024.1\5_module\1 занятие\practice\venv\lib\site-packages\telegram\ext\extbot.py", line 199, in _message
    result = super()._message(
  File "D:\1_PT_START_2024.1\5_module\1 занятие\practice\venv\lib\site-packages\telegram\bot.py", line 332, in _message
    result = self._post(endpoint, data, timeout=timeout, api_kwargs=api_kwargs)
  File "D:\1_PT_START_2024.1\5_module\1 занятие\practice\venv\lib\site-packages\telegram\bot.py", line 295, in _post
    return self.request.post(
  File "D:\1_PT_START_2024.1\5_module\1 занятие\practice\venv\lib\site-packages\telegram\utils\request.py", line 356, in post
    result = self._request_wrapper(
  File "D:\1_PT_START_2024.1\5_module\1 занятие\practice\venv\lib\site-packages\telegram\utils\request.py", line 279, in _request_wrapper
    raise BadRequest(message)
telegram.error.BadRequest: Message is too long
2024-05-06 17:53:41,275 - telegram.ext.updater - INFO - Received signal 2 (SIGINT), stopping...
2024-05-06 17:53:41,276 - apscheduler.scheduler - INFO - Scheduler has been shut down
2024-05-06 17:53:43,670 - apscheduler.scheduler - INFO - Scheduler started
2024-05-06 17:53:45,859 - paramiko.transport - INFO - Connected (version 2.0, client OpenSSH_9.6p1)
2024-05-06 17:53:45,987 - paramiko.transport - INFO - Authentication (publickey) failed.
2024-05-06 17:53:45,995 - paramiko.transport - INFO - Authentication (publickey) failed.
2024-05-06 17:53:46,023 - paramiko.transport - INFO - Authentication (password) successful!
2024-05-06 17:56:17,154 - telegram.ext.updater - INFO - Received signal 2 (SIGINT), stopping...
2024-05-06 17:56:17,155 - apscheduler.scheduler - INFO - Scheduler has been shut down
2024-05-06 17:56:24,741 - apscheduler.scheduler - INFO - Scheduler started
2024-05-06 17:56:26,502 - paramiko.transport - INFO - Connected (version 2.0, client OpenSSH_9.6p1)
2024-05-06 17:56:26,630 - paramiko.transport - INFO - Authentication (publickey) failed.
2024-05-06 17:56:26,638 - paramiko.transport - INFO - Authentication (publickey) failed.
2024-05-06 17:56:26,693 - paramiko.transport - INFO - Authentication (password) successful!
2024-05-06 17:57:35,940 - telegram.ext.updater - INFO - Received signal 2 (SIGINT), stopping...
2024-05-06 17:57:35,940 - apscheduler.scheduler - INFO - Scheduler has been shut down
2024-05-06 17:57:55,217 - apscheduler.scheduler - INFO - Scheduler started
2024-05-06 17:58:01,289 - paramiko.transport - INFO - Connected (version 2.0, client OpenSSH_9.6p1)
2024-05-06 17:58:01,416 - paramiko.transport - INFO - Authentication (publickey) failed.
2024-05-06 17:58:01,424 - paramiko.transport - INFO - Authentication (publickey) failed.
2024-05-06 17:58:01,453 - paramiko.transport - INFO - Authentication (password) successful!
2024-05-06 17:58:03,506 - telegram.ext.dispatcher - ERROR - No error handlers are registered, logging exception.
Traceback (most recent call last):
  File "D:\1_PT_START_2024.1\5_module\1 занятие\practice\venv\lib\site-packages\telegram\ext\dispatcher.py", line 555, in process_update
    handler.handle_update(update, self, check, context)
  File "D:\1_PT_START_2024.1\5_module\1 занятие\practice\venv\lib\site-packages\telegram\ext\handler.py", line 198, in handle_update
    return self.callback(update, context)
  File "D:\1_PT_START_2024.1\5_module\1 занятие\practice\monitoring.py", line 90, in get_apt_list
    update.message.reply_text(response)
  File "D:\1_PT_START_2024.1\5_module\1 занятие\practice\venv\lib\site-packages\telegram\message.py", line 764, in reply_text
    return self.bot.send_message(
  File "D:\1_PT_START_2024.1\5_module\1 занятие\practice\venv\lib\site-packages\telegram\bot.py", line 130, in decorator
    result = func(*args, **kwargs)
  File "D:\1_PT_START_2024.1\5_module\1 занятие\practice\venv\lib\site-packages\telegram\bot.py", line 513, in send_message
    return self._message(  # type: ignore[return-value]
  File "D:\1_PT_START_2024.1\5_module\1 занятие\practice\venv\lib\site-packages\telegram\ext\extbot.py", line 199, in _message
    result = super()._message(
  File "D:\1_PT_START_2024.1\5_module\1 занятие\practice\venv\lib\site-packages\telegram\bot.py", line 332, in _message
    result = self._post(endpoint, data, timeout=timeout, api_kwargs=api_kwargs)
  File "D:\1_PT_START_2024.1\5_module\1 занятие\practice\venv\lib\site-packages\telegram\bot.py", line 295, in _post
    return self.request.post(
  File "D:\1_PT_START_2024.1\5_module\1 занятие\practice\venv\lib\site-packages\telegram\utils\request.py", line 356, in post
    result = self._request_wrapper(
  File "D:\1_PT_START_2024.1\5_module\1 занятие\practice\venv\lib\site-packages\telegram\utils\request.py", line 285, in _request_wrapper
    raise NetworkError(
telegram.error.NetworkError: File too large. Check telegram api limits https://core.telegram.org/bots/api#senddocument
2024-05-06 17:58:37,791 - telegram.ext.updater - INFO - Received signal 2 (SIGINT), stopping...
2024-05-06 17:58:37,792 - apscheduler.scheduler - INFO - Scheduler has been shut down
2024-05-06 17:58:40,865 - apscheduler.scheduler - INFO - Scheduler started
2024-05-06 17:58:43,672 - paramiko.transport - INFO - Connected (version 2.0, client OpenSSH_9.6p1)
2024-05-06 17:58:43,800 - paramiko.transport - INFO - Authentication (publickey) failed.
2024-05-06 17:58:43,808 - paramiko.transport - INFO - Authentication (publickey) failed.
2024-05-06 17:58:43,863 - paramiko.transport - INFO - Authentication (password) successful!
2024-05-06 18:01:34,344 - telegram.ext.updater - INFO - Received signal 2 (SIGINT), stopping...
2024-05-06 18:01:34,344 - apscheduler.scheduler - INFO - Scheduler has been shut down
2024-05-06 18:02:15,686 - apscheduler.scheduler - INFO - Scheduler started
2024-05-06 18:02:16,201 - paramiko.transport - INFO - Connected (version 2.0, client OpenSSH_9.6p1)
2024-05-06 18:02:16,333 - paramiko.transport - INFO - Authentication (publickey) failed.
2024-05-06 18:02:16,341 - paramiko.transport - INFO - Authentication (publickey) failed.
2024-05-06 18:02:16,369 - paramiko.transport - INFO - Authentication (password) successful!
2024-05-06 18:05:18,422 - telegram.ext.updater - INFO - Received signal 2 (SIGINT), stopping...
2024-05-06 18:05:18,422 - apscheduler.scheduler - INFO - Scheduler has been shut down
2024-05-07 12:55:17,472 - apscheduler.scheduler - INFO - Scheduler started
2024-05-07 12:55:44,217 - telegram.ext.dispatcher - ERROR - No error handlers are registered, logging exception.
Traceback (most recent call last):
  File "D:\1_PT_START_2024.1\5_module\theory\venv\lib\site-packages\telegram\ext\dispatcher.py", line 555, in process_update
    handler.handle_update(update, self, check, context)
  File "D:\1_PT_START_2024.1\5_module\theory\venv\lib\site-packages\telegram\ext\handler.py", line 198, in handle_update
    return self.callback(update, context)
  File "D:\1_PT_START_2024.1\5_module\practice_project\monitoring.py", line 85, in get_apt_list
    response = execute_ssh_command(host, port, username, password, "apt list | tail -n 20")
  File "D:\1_PT_START_2024.1\5_module\practice_project\monitoring.py", line 14, in execute_ssh_command
    client.connect(hostname=host, port=port, username=username, password=password)
  File "D:\1_PT_START_2024.1\5_module\theory\venv\lib\site-packages\paramiko\client.py", line 386, in connect
    sock.connect(addr)
TimeoutError: [WinError 10060] Попытка установить соединение была безуспешной, т.к. от другого компьютера за требуемое время не получен нужный отклик, или было разорвано уже установленное соединение из-за неверного отклика уже подключенного компьютера
2024-05-07 12:56:30,130 - telegram.ext.dispatcher - ERROR - No error handlers are registered, logging exception.
Traceback (most recent call last):
  File "D:\1_PT_START_2024.1\5_module\theory\venv\lib\site-packages\telegram\ext\dispatcher.py", line 555, in process_update
    handler.handle_update(update, self, check, context)
  File "D:\1_PT_START_2024.1\5_module\theory\venv\lib\site-packages\telegram\ext\handler.py", line 198, in handle_update
    return self.callback(update, context)
  File "D:\1_PT_START_2024.1\5_module\practice_project\monitoring.py", line 85, in get_apt_list
    response = execute_ssh_command(host, port, username, password, "apt list | tail -n 20")
  File "D:\1_PT_START_2024.1\5_module\practice_project\monitoring.py", line 14, in execute_ssh_command
    client.connect(hostname=host, port=port, username=username, password=password)
  File "D:\1_PT_START_2024.1\5_module\theory\venv\lib\site-packages\paramiko\client.py", line 386, in connect
    sock.connect(addr)
TimeoutError: [WinError 10060] Попытка установить соединение была безуспешной, т.к. от другого компьютера за требуемое время не получен нужный отклик, или было разорвано уже установленное соединение из-за неверного отклика уже подключенного компьютера
2024-05-07 12:56:51,186 - telegram.ext.dispatcher - ERROR - No error handlers are registered, logging exception.
Traceback (most recent call last):
  File "D:\1_PT_START_2024.1\5_module\theory\venv\lib\site-packages\telegram\ext\dispatcher.py", line 555, in process_update
    handler.handle_update(update, self, check, context)
  File "D:\1_PT_START_2024.1\5_module\theory\venv\lib\site-packages\telegram\ext\handler.py", line 198, in handle_update
    return self.callback(update, context)
  File "D:\1_PT_START_2024.1\5_module\practice_project\monitoring.py", line 94, in get_services
    response = execute_ssh_command(host, port, username, password, "service --status-all")
  File "D:\1_PT_START_2024.1\5_module\practice_project\monitoring.py", line 14, in execute_ssh_command
    client.connect(hostname=host, port=port, username=username, password=password)
  File "D:\1_PT_START_2024.1\5_module\theory\venv\lib\site-packages\paramiko\client.py", line 386, in connect
    sock.connect(addr)
TimeoutError: [WinError 10060] Попытка установить соединение была безуспешной, т.к. от другого компьютера за требуемое время не получен нужный отклик, или было разорвано уже установленное соединение из-за неверного отклика уже подключенного компьютера
2024-05-07 12:57:22,277 - telegram.ext.updater - INFO - Received signal 2 (SIGINT), stopping...
2024-05-07 12:57:22,277 - apscheduler.scheduler - INFO - Scheduler has been shut down
2024-05-07 13:00:46,056 - apscheduler.scheduler - INFO - Scheduler started
2024-05-07 13:00:53,064 - paramiko.transport - INFO - Connected (version 2.0, client OpenSSH_9.6p1)
2024-05-07 13:00:53,199 - paramiko.transport - INFO - Authentication (publickey) failed.
2024-05-07 13:00:53,207 - paramiko.transport - INFO - Authentication (publickey) failed.
2024-05-07 13:00:53,262 - paramiko.transport - INFO - Authentication (password) successful!
2024-05-07 13:00:57,908 - paramiko.transport - INFO - Connected (version 2.0, client OpenSSH_9.6p1)
2024-05-07 13:00:58,039 - paramiko.transport - INFO - Authentication (publickey) failed.
2024-05-07 13:00:58,048 - paramiko.transport - INFO - Authentication (publickey) failed.
2024-05-07 13:00:58,076 - paramiko.transport - INFO - Authentication (password) successful!
2024-05-07 13:01:10,361 - telegram.ext.updater - INFO - Received signal 2 (SIGINT), stopping...
2024-05-07 13:01:10,362 - apscheduler.scheduler - INFO - Scheduler has been shut down
2024-05-08 19:35:27,284 - apscheduler.scheduler - INFO - Scheduler started
2024-05-08 19:36:40,634 - telegram.ext.updater - INFO - Received signal 2 (SIGINT), stopping...
2024-05-08 19:36:40,634 - apscheduler.scheduler - INFO - Scheduler has been shut down
2024-05-08 19:41:03,459 - apscheduler.scheduler - INFO - Scheduler started
2024-05-08 19:41:05,601 - paramiko.transport - INFO - Connected (version 2.0, client OpenSSH_9.2p1)
2024-05-08 19:41:05,738 - paramiko.transport - INFO - Authentication (publickey) failed.
2024-05-08 19:41:05,749 - paramiko.transport - INFO - Authentication (publickey) failed.
2024-05-08 19:41:05,785 - paramiko.transport - INFO - Authentication (password) successful!
2024-05-08 19:43:53,018 - telegram.ext.updater - INFO - Received signal 2 (SIGINT), stopping...
2024-05-08 19:43:53,019 - apscheduler.scheduler - INFO - Scheduler has been shut down
2024-05-08 20:32:56,682 - apscheduler.scheduler - INFO - Scheduler started
2024-05-08 20:33:07,533 - paramiko.transport - INFO - Connected (version 2.0, client OpenSSH_9.2p1)
2024-05-08 20:33:07,674 - paramiko.transport - INFO - Authentication (publickey) failed.
2024-05-08 20:33:07,685 - paramiko.transport - INFO - Authentication (publickey) failed.
2024-05-08 20:33:07,722 - paramiko.transport - INFO - Authentication (password) successful!
2024-05-08 20:34:24,544 - paramiko.transport - INFO - Connected (version 2.0, client OpenSSH_9.2p1)
2024-05-08 20:34:24,691 - paramiko.transport - INFO - Authentication (publickey) failed.
2024-05-08 20:34:24,702 - paramiko.transport - INFO - Authentication (publickey) failed.
2024-05-08 20:34:24,739 - paramiko.transport - INFO - Authentication (password) successful!
2024-05-08 20:42:50,065 - telegram.ext.updater - INFO - Received signal 2 (SIGINT), stopping...
2024-05-08 20:42:50,066 - apscheduler.scheduler - INFO - Scheduler has been shut down
2024-05-08 20:42:52,151 - apscheduler.scheduler - INFO - Scheduler started
2024-05-08 20:42:59,870 - paramiko.transport - INFO - Connected (version 2.0, client OpenSSH_9.2p1)
2024-05-08 20:43:00,003 - paramiko.transport - INFO - Authentication (publickey) failed.
2024-05-08 20:43:00,014 - paramiko.transport - INFO - Authentication (publickey) failed.
2024-05-08 20:43:00,051 - paramiko.transport - INFO - Authentication (password) successful!
2024-05-08 20:43:14,319 - paramiko.transport - INFO - Connected (version 2.0, client OpenSSH_9.2p1)
2024-05-08 20:43:14,445 - paramiko.transport - INFO - Authentication (publickey) failed.
2024-05-08 20:43:14,456 - paramiko.transport - INFO - Authentication (publickey) failed.
2024-05-08 20:43:14,493 - paramiko.transport - INFO - Authentication (password) successful!
2024-05-08 20:43:20,203 - telegram.ext.updater - INFO - Received signal 2 (SIGINT), stopping...
2024-05-08 20:43:20,204 - apscheduler.scheduler - INFO - Scheduler has been shut down
2024-05-09 12:39:20,459 - apscheduler.scheduler - INFO - Scheduler started
2024-05-09 12:40:49,803 - telegram.ext.updater - INFO - Received signal 2 (SIGINT), stopping...
2024-05-09 12:40:49,803 - apscheduler.scheduler - INFO - Scheduler has been shut down
2024-05-09 12:45:43,472 - apscheduler.scheduler - INFO - Scheduler started
2024-05-09 12:48:31,740 - telegram.ext.updater - INFO - Received signal 2 (SIGINT), stopping...
2024-05-09 12:48:31,740 - apscheduler.scheduler - INFO - Scheduler has been shut down
2024-05-09 13:11:41,215 - apscheduler.scheduler - INFO - Scheduler started
2024-05-09 13:12:20,760 - telegram.ext.dispatcher - ERROR - No error handlers are registered, logging exception.
Traceback (most recent call last):
  File "D:\1_PT_START_2024.1\5_module\theory\venv\lib\site-packages\telegram\ext\dispatcher.py", line 555, in process_update
    handler.handle_update(update, self, check, context)
  File "D:\1_PT_START_2024.1\5_module\theory\venv\lib\site-packages\telegram\ext\conversationhandler.py", line 626, in handle_update
    new_state = handler.handle_update(update, dispatcher, check_result, context)
  File "D:\1_PT_START_2024.1\5_module\theory\venv\lib\site-packages\telegram\ext\handler.py", line 198, in handle_update
    return self.callback(update, context)
  File "D:\1_PT_START_2024.1\5_module\practice_project\db_practice.py", line 66, in save_phone_numbers
    conn = psycopg2.connect(
  File "D:\1_PT_START_2024.1\5_module\theory\venv\lib\site-packages\psycopg2\__init__.py", line 122, in connect
    conn = _connect(dsn, connection_factory=connection_factory, **kwasync)
psycopg2.OperationalError: connection to server at "192.168.1.51", port 22 failed: server closed the connection unexpectedly
	This probably means the server terminated abnormally
	before or while processing the request.
SSL SYSCALL error: Connection reset by peer (0x00002746/10054)
connection to server at "192.168.1.51", port 22 failed: expected authentication request from server, but received S

2024-05-09 13:12:48,289 - telegram.ext.updater - INFO - Received signal 2 (SIGINT), stopping...
2024-05-09 13:12:48,289 - apscheduler.scheduler - INFO - Scheduler has been shut down
2024-05-09 13:13:17,990 - apscheduler.scheduler - INFO - Scheduler started
2024-05-09 13:13:45,592 - telegram.ext.dispatcher - ERROR - No error handlers are registered, logging exception.
Traceback (most recent call last):
  File "D:\1_PT_START_2024.1\5_module\theory\venv\lib\site-packages\telegram\ext\dispatcher.py", line 555, in process_update
    handler.handle_update(update, self, check, context)
  File "D:\1_PT_START_2024.1\5_module\theory\venv\lib\site-packages\telegram\ext\conversationhandler.py", line 626, in handle_update
    new_state = handler.handle_update(update, dispatcher, check_result, context)
  File "D:\1_PT_START_2024.1\5_module\theory\venv\lib\site-packages\telegram\ext\handler.py", line 198, in handle_update
    return self.callback(update, context)
  File "D:\1_PT_START_2024.1\5_module\practice_project\db_practice.py", line 66, in save_phone_numbers
    conn = psycopg2.connect(
  File "D:\1_PT_START_2024.1\5_module\theory\venv\lib\site-packages\psycopg2\__init__.py", line 122, in connect
    conn = _connect(dsn, connection_factory=connection_factory, **kwasync)
psycopg2.OperationalError: connection to server at "192.168.1.51", port 5432 failed: FATAL:  no pg_hba.conf entry for host "192.168.1.136", user "postgres", database "db_practice", SSL encryption
connection to server at "192.168.1.51", port 5432 failed: FATAL:  no pg_hba.conf entry for host "192.168.1.136", user "postgres", database "db_practice", no encryption

2024-05-09 13:14:25,054 - telegram.ext.updater - INFO - Received signal 2 (SIGINT), stopping...
2024-05-09 13:14:25,055 - apscheduler.scheduler - INFO - Scheduler has been shut down
2024-05-09 13:17:53,279 - apscheduler.scheduler - INFO - Scheduler started
2024-05-09 13:18:12,142 - telegram.ext.dispatcher - ERROR - No error handlers are registered, logging exception.
Traceback (most recent call last):
  File "D:\1_PT_START_2024.1\5_module\theory\venv\lib\site-packages\telegram\ext\dispatcher.py", line 555, in process_update
    handler.handle_update(update, self, check, context)
  File "D:\1_PT_START_2024.1\5_module\theory\venv\lib\site-packages\telegram\ext\conversationhandler.py", line 626, in handle_update
    new_state = handler.handle_update(update, dispatcher, check_result, context)
  File "D:\1_PT_START_2024.1\5_module\theory\venv\lib\site-packages\telegram\ext\handler.py", line 198, in handle_update
    return self.callback(update, context)
  File "D:\1_PT_START_2024.1\5_module\practice_project\db_practice.py", line 66, in save_phone_numbers
    conn = psycopg2.connect(
  File "D:\1_PT_START_2024.1\5_module\theory\venv\lib\site-packages\psycopg2\__init__.py", line 122, in connect
    conn = _connect(dsn, connection_factory=connection_factory, **kwasync)
psycopg2.OperationalError: connection to server at "192.168.1.51", port 5432 failed: FATAL:  password authentication failed for user "postgres"
connection to server at "192.168.1.51", port 5432 failed: FATAL:  password authentication failed for user "postgres"

2024-05-09 13:19:05,677 - telegram.ext.updater - INFO - Received signal 2 (SIGINT), stopping...
2024-05-09 13:19:05,677 - apscheduler.scheduler - INFO - Scheduler has been shut down
2024-05-09 13:23:01,138 - apscheduler.scheduler - INFO - Scheduler started
2024-05-09 13:23:10,745 - telegram.ext.dispatcher - ERROR - No error handlers are registered, logging exception.
Traceback (most recent call last):
  File "D:\1_PT_START_2024.1\5_module\theory\venv\lib\site-packages\telegram\ext\dispatcher.py", line 555, in process_update
    handler.handle_update(update, self, check, context)
  File "D:\1_PT_START_2024.1\5_module\theory\venv\lib\site-packages\telegram\ext\conversationhandler.py", line 626, in handle_update
    new_state = handler.handle_update(update, dispatcher, check_result, context)
  File "D:\1_PT_START_2024.1\5_module\theory\venv\lib\site-packages\telegram\ext\handler.py", line 198, in handle_update
    return self.callback(update, context)
  File "D:\1_PT_START_2024.1\5_module\practice_project\db_practice.py", line 66, in save_phone_numbers
    conn = psycopg2.connect(
  File "D:\1_PT_START_2024.1\5_module\theory\venv\lib\site-packages\psycopg2\__init__.py", line 122, in connect
    conn = _connect(dsn, connection_factory=connection_factory, **kwasync)
psycopg2.OperationalError: connection to server at "192.168.1.51", port 5432 failed: FATAL:  password authentication failed for user "postgres"
connection to server at "192.168.1.51", port 5432 failed: FATAL:  password authentication failed for user "postgres"

2024-05-09 13:25:30,408 - telegram.ext.updater - INFO - Received signal 2 (SIGINT), stopping...
2024-05-09 13:25:30,408 - apscheduler.scheduler - INFO - Scheduler has been shut down
2024-05-09 13:25:34,676 - apscheduler.scheduler - INFO - Scheduler started
2024-05-09 13:25:42,979 - telegram.ext.dispatcher - ERROR - No error handlers are registered, logging exception.
Traceback (most recent call last):
  File "D:\1_PT_START_2024.1\5_module\theory\venv\lib\site-packages\telegram\ext\dispatcher.py", line 555, in process_update
    handler.handle_update(update, self, check, context)
  File "D:\1_PT_START_2024.1\5_module\theory\venv\lib\site-packages\telegram\ext\conversationhandler.py", line 626, in handle_update
    new_state = handler.handle_update(update, dispatcher, check_result, context)
  File "D:\1_PT_START_2024.1\5_module\theory\venv\lib\site-packages\telegram\ext\handler.py", line 198, in handle_update
    return self.callback(update, context)
  File "D:\1_PT_START_2024.1\5_module\practice_project\db_practice.py", line 66, in save_phone_numbers
    conn = psycopg2.connect(
  File "D:\1_PT_START_2024.1\5_module\theory\venv\lib\site-packages\psycopg2\__init__.py", line 122, in connect
    conn = _connect(dsn, connection_factory=connection_factory, **kwasync)
psycopg2.OperationalError: connection to server at "192.168.1.51", port 5432 failed: FATAL:  password authentication failed for user "postgres"
connection to server at "192.168.1.51", port 5432 failed: FATAL:  password authentication failed for user "postgres"

2024-05-09 13:30:26,888 - telegram.ext.updater - INFO - Received signal 2 (SIGINT), stopping...
2024-05-09 13:30:26,888 - apscheduler.scheduler - INFO - Scheduler has been shut down
2024-05-09 13:31:04,561 - apscheduler.scheduler - INFO - Scheduler started
2024-05-09 13:31:20,978 - telegram.ext.dispatcher - ERROR - No error handlers are registered, logging exception.
Traceback (most recent call last):
  File "D:\1_PT_START_2024.1\5_module\theory\venv\lib\site-packages\telegram\ext\dispatcher.py", line 555, in process_update
    handler.handle_update(update, self, check, context)
  File "D:\1_PT_START_2024.1\5_module\theory\venv\lib\site-packages\telegram\ext\conversationhandler.py", line 626, in handle_update
    new_state = handler.handle_update(update, dispatcher, check_result, context)
  File "D:\1_PT_START_2024.1\5_module\theory\venv\lib\site-packages\telegram\ext\handler.py", line 198, in handle_update
    return self.callback(update, context)
  File "D:\1_PT_START_2024.1\5_module\practice_project\db_practice.py", line 67, in save_phone_numbers
    conn = psycopg2.connect(
  File "D:\1_PT_START_2024.1\5_module\theory\venv\lib\site-packages\psycopg2\__init__.py", line 122, in connect
    conn = _connect(dsn, connection_factory=connection_factory, **kwasync)
psycopg2.OperationalError: connection to server at "192.168.1.51", port 5432 failed: FATAL:  password authentication failed for user "postgres"
connection to server at "192.168.1.51", port 5432 failed: FATAL:  password authentication failed for user "postgres"

2024-05-09 13:40:52,967 - telegram.ext.updater - INFO - Received signal 2 (SIGINT), stopping...
2024-05-09 13:40:52,968 - apscheduler.scheduler - INFO - Scheduler has been shut down
2024-05-09 13:57:31,534 - apscheduler.scheduler - INFO - Scheduler started
2024-05-09 13:57:34,188 - telegram.ext.updater - INFO - Received signal 2 (SIGINT), stopping...
2024-05-09 13:57:34,189 - apscheduler.scheduler - INFO - Scheduler has been shut down
2024-05-09 14:04:03,753 - apscheduler.scheduler - INFO - Scheduler started
2024-05-09 14:04:43,839 - paramiko.transport - ERROR - Exception (client): Error reading SSH protocol banner
2024-05-09 14:04:43,841 - paramiko.transport - ERROR - Traceback (most recent call last):
2024-05-09 14:04:43,841 - paramiko.transport - ERROR -   File "D:\1_PT_START_2024.1\5_module\theory\venv\lib\site-packages\paramiko\transport.py", line 2327, in _check_banner
2024-05-09 14:04:43,841 - paramiko.transport - ERROR -     buf = self.packetizer.readline(timeout)
2024-05-09 14:04:43,841 - paramiko.transport - ERROR -   File "D:\1_PT_START_2024.1\5_module\theory\venv\lib\site-packages\paramiko\packet.py", line 381, in readline
2024-05-09 14:04:43,841 - paramiko.transport - ERROR -     buf += self._read_timeout(timeout)
2024-05-09 14:04:43,841 - paramiko.transport - ERROR -   File "D:\1_PT_START_2024.1\5_module\theory\venv\lib\site-packages\paramiko\packet.py", line 618, in _read_timeout
2024-05-09 14:04:43,841 - paramiko.transport - ERROR -     raise EOFError()
2024-05-09 14:04:43,841 - paramiko.transport - ERROR - EOFError
2024-05-09 14:04:43,842 - paramiko.transport - ERROR - 
2024-05-09 14:04:43,842 - paramiko.transport - ERROR - During handling of the above exception, another exception occurred:
2024-05-09 14:04:43,842 - paramiko.transport - ERROR - 
2024-05-09 14:04:43,842 - paramiko.transport - ERROR - Traceback (most recent call last):
2024-05-09 14:04:43,842 - paramiko.transport - ERROR -   File "D:\1_PT_START_2024.1\5_module\theory\venv\lib\site-packages\paramiko\transport.py", line 2143, in run
2024-05-09 14:04:43,842 - paramiko.transport - ERROR -     self._check_banner()
2024-05-09 14:04:43,842 - paramiko.transport - ERROR -   File "D:\1_PT_START_2024.1\5_module\theory\venv\lib\site-packages\paramiko\transport.py", line 2331, in _check_banner
2024-05-09 14:04:43,842 - paramiko.transport - ERROR -     raise SSHException(
2024-05-09 14:04:43,842 - paramiko.transport - ERROR - paramiko.ssh_exception.SSHException: Error reading SSH protocol banner
2024-05-09 14:04:43,842 - paramiko.transport - ERROR - 
2024-05-09 14:04:43,842 - telegram.ext.dispatcher - ERROR - No error handlers are registered, logging exception.
Traceback (most recent call last):
  File "D:\1_PT_START_2024.1\5_module\theory\venv\lib\site-packages\paramiko\transport.py", line 2327, in _check_banner
    buf = self.packetizer.readline(timeout)
  File "D:\1_PT_START_2024.1\5_module\theory\venv\lib\site-packages\paramiko\packet.py", line 381, in readline
    buf += self._read_timeout(timeout)
  File "D:\1_PT_START_2024.1\5_module\theory\venv\lib\site-packages\paramiko\packet.py", line 618, in _read_timeout
    raise EOFError()
EOFError

During handling of the above exception, another exception occurred:

Traceback (most recent call last):
  File "D:\1_PT_START_2024.1\5_module\theory\venv\lib\site-packages\telegram\ext\dispatcher.py", line 555, in process_update
    handler.handle_update(update, self, check, context)
  File "D:\1_PT_START_2024.1\5_module\theory\venv\lib\site-packages\telegram\ext\handler.py", line 198, in handle_update
    return self.callback(update, context)
  File "D:\1_PT_START_2024.1\5_module\practice_project\db_practice.py", line 55, in get_phones
    response = execute_ssh_command(host, port, username, password, "psql -U postgres -d db_practice -c 'SELECT * FROM phones;'")
  File "D:\1_PT_START_2024.1\5_module\practice_project\db_practice.py", line 40, in execute_ssh_command
    client.connect(hostname=host, port=port, username=username, password=password)
  File "D:\1_PT_START_2024.1\5_module\theory\venv\lib\site-packages\paramiko\client.py", line 451, in connect
    t.start_client(timeout=timeout)
  File "D:\1_PT_START_2024.1\5_module\theory\venv\lib\site-packages\paramiko\transport.py", line 738, in start_client
    raise e
  File "D:\1_PT_START_2024.1\5_module\theory\venv\lib\site-packages\paramiko\transport.py", line 2143, in run
    self._check_banner()
  File "D:\1_PT_START_2024.1\5_module\theory\venv\lib\site-packages\paramiko\transport.py", line 2331, in _check_banner
    raise SSHException(
paramiko.ssh_exception.SSHException: Error reading SSH protocol banner
2024-05-09 14:05:39,806 - telegram.ext.updater - INFO - Received signal 2 (SIGINT), stopping...
2024-05-09 14:05:39,806 - apscheduler.scheduler - INFO - Scheduler has been shut down
2024-05-09 14:07:06,395 - apscheduler.scheduler - INFO - Scheduler started
2024-05-09 14:07:08,527 - paramiko.transport - INFO - Connected (version 2.0, client OpenSSH_9.2p1)
2024-05-09 14:07:08,699 - paramiko.transport - INFO - Authentication (publickey) failed.
2024-05-09 14:07:08,710 - paramiko.transport - INFO - Authentication (publickey) failed.
2024-05-09 14:07:08,842 - paramiko.transport - INFO - Authentication (password) successful!
2024-05-09 14:07:09,308 - telegram.ext.dispatcher - ERROR - No error handlers are registered, logging exception.
Traceback (most recent call last):
  File "D:\1_PT_START_2024.1\5_module\theory\venv\lib\site-packages\telegram\ext\dispatcher.py", line 555, in process_update
    handler.handle_update(update, self, check, context)
  File "D:\1_PT_START_2024.1\5_module\theory\venv\lib\site-packages\telegram\ext\handler.py", line 198, in handle_update
    return self.callback(update, context)
  File "D:\1_PT_START_2024.1\5_module\practice_project\db_practice.py", line 58, in get_phones
    update.message.reply_text(response)
  File "D:\1_PT_START_2024.1\5_module\theory\venv\lib\site-packages\telegram\message.py", line 764, in reply_text
    return self.bot.send_message(
  File "D:\1_PT_START_2024.1\5_module\theory\venv\lib\site-packages\telegram\bot.py", line 130, in decorator
    result = func(*args, **kwargs)
  File "D:\1_PT_START_2024.1\5_module\theory\venv\lib\site-packages\telegram\bot.py", line 513, in send_message
    return self._message(  # type: ignore[return-value]
  File "D:\1_PT_START_2024.1\5_module\theory\venv\lib\site-packages\telegram\ext\extbot.py", line 199, in _message
    result = super()._message(
  File "D:\1_PT_START_2024.1\5_module\theory\venv\lib\site-packages\telegram\bot.py", line 332, in _message
    result = self._post(endpoint, data, timeout=timeout, api_kwargs=api_kwargs)
  File "D:\1_PT_START_2024.1\5_module\theory\venv\lib\site-packages\telegram\bot.py", line 295, in _post
    return self.request.post(
  File "D:\1_PT_START_2024.1\5_module\theory\venv\lib\site-packages\telegram\utils\request.py", line 356, in post
    result = self._request_wrapper(
  File "D:\1_PT_START_2024.1\5_module\theory\venv\lib\site-packages\telegram\utils\request.py", line 279, in _request_wrapper
    raise BadRequest(message)
telegram.error.BadRequest: Message text is empty
2024-05-09 14:10:26,497 - paramiko.transport - INFO - Connected (version 2.0, client OpenSSH_9.2p1)
2024-05-09 14:10:26,629 - paramiko.transport - INFO - Authentication (publickey) failed.
2024-05-09 14:10:26,639 - paramiko.transport - INFO - Authentication (publickey) failed.
2024-05-09 14:10:26,771 - paramiko.transport - INFO - Authentication (password) successful!
2024-05-09 14:10:27,019 - telegram.ext.dispatcher - ERROR - No error handlers are registered, logging exception.
Traceback (most recent call last):
  File "D:\1_PT_START_2024.1\5_module\theory\venv\lib\site-packages\telegram\ext\dispatcher.py", line 555, in process_update
    handler.handle_update(update, self, check, context)
  File "D:\1_PT_START_2024.1\5_module\theory\venv\lib\site-packages\telegram\ext\handler.py", line 198, in handle_update
    return self.callback(update, context)
  File "D:\1_PT_START_2024.1\5_module\practice_project\db_practice.py", line 54, in get_emails
    update.message.reply_text(response)
  File "D:\1_PT_START_2024.1\5_module\theory\venv\lib\site-packages\telegram\message.py", line 764, in reply_text
    return self.bot.send_message(
  File "D:\1_PT_START_2024.1\5_module\theory\venv\lib\site-packages\telegram\bot.py", line 130, in decorator
    result = func(*args, **kwargs)
  File "D:\1_PT_START_2024.1\5_module\theory\venv\lib\site-packages\telegram\bot.py", line 513, in send_message
    return self._message(  # type: ignore[return-value]
  File "D:\1_PT_START_2024.1\5_module\theory\venv\lib\site-packages\telegram\ext\extbot.py", line 199, in _message
    result = super()._message(
  File "D:\1_PT_START_2024.1\5_module\theory\venv\lib\site-packages\telegram\bot.py", line 332, in _message
    result = self._post(endpoint, data, timeout=timeout, api_kwargs=api_kwargs)
  File "D:\1_PT_START_2024.1\5_module\theory\venv\lib\site-packages\telegram\bot.py", line 295, in _post
    return self.request.post(
  File "D:\1_PT_START_2024.1\5_module\theory\venv\lib\site-packages\telegram\utils\request.py", line 356, in post
    result = self._request_wrapper(
  File "D:\1_PT_START_2024.1\5_module\theory\venv\lib\site-packages\telegram\utils\request.py", line 279, in _request_wrapper
    raise BadRequest(message)
telegram.error.BadRequest: Message text is empty
2024-05-09 14:10:49,254 - telegram.ext.updater - INFO - Received signal 2 (SIGINT), stopping...
2024-05-09 14:10:49,254 - apscheduler.scheduler - INFO - Scheduler has been shut down
2024-05-09 14:16:53,451 - apscheduler.scheduler - INFO - Scheduler started
2024-05-09 14:17:37,245 - telegram.ext.updater - INFO - Received signal 2 (SIGINT), stopping...
2024-05-09 14:17:37,245 - apscheduler.scheduler - INFO - Scheduler has been shut down
2024-05-09 14:19:57,425 - apscheduler.scheduler - INFO - Scheduler started
2024-05-09 14:20:58,941 - telegram.ext.updater - INFO - Received signal 2 (SIGINT), stopping...
2024-05-09 14:20:58,941 - apscheduler.scheduler - INFO - Scheduler has been shut down
2024-05-09 14:21:01,228 - apscheduler.scheduler - INFO - Scheduler started
2024-05-09 14:22:45,393 - telegram.ext.updater - INFO - Received signal 2 (SIGINT), stopping...
2024-05-09 14:22:45,393 - apscheduler.scheduler - INFO - Scheduler has been shut down
2024-05-09 14:22:47,947 - apscheduler.scheduler - INFO - Scheduler started
2024-05-09 14:22:52,456 - paramiko.transport - INFO - Connected (version 2.0, client OpenSSH_9.2p1)
2024-05-09 14:22:52,615 - paramiko.transport - INFO - Authentication (publickey) failed.
2024-05-09 14:22:52,626 - paramiko.transport - INFO - Authentication (publickey) failed.
2024-05-09 14:22:52,661 - paramiko.transport - INFO - Authentication (password) successful!
2024-05-09 14:22:53,188 - telegram.ext.dispatcher - ERROR - No error handlers are registered, logging exception.
Traceback (most recent call last):
  File "D:\1_PT_START_2024.1\5_module\theory\venv\lib\site-packages\telegram\ext\dispatcher.py", line 555, in process_update
    handler.handle_update(update, self, check, context)
  File "D:\1_PT_START_2024.1\5_module\theory\venv\lib\site-packages\telegram\ext\handler.py", line 198, in handle_update
    return self.callback(update, context)
  File "D:\1_PT_START_2024.1\5_module\practice_project\db_practice.py", line 50, in get_replica
    update.message.reply_text(response)
  File "D:\1_PT_START_2024.1\5_module\theory\venv\lib\site-packages\telegram\message.py", line 764, in reply_text
    return self.bot.send_message(
  File "D:\1_PT_START_2024.1\5_module\theory\venv\lib\site-packages\telegram\bot.py", line 130, in decorator
    result = func(*args, **kwargs)
  File "D:\1_PT_START_2024.1\5_module\theory\venv\lib\site-packages\telegram\bot.py", line 513, in send_message
    return self._message(  # type: ignore[return-value]
  File "D:\1_PT_START_2024.1\5_module\theory\venv\lib\site-packages\telegram\ext\extbot.py", line 199, in _message
    result = super()._message(
  File "D:\1_PT_START_2024.1\5_module\theory\venv\lib\site-packages\telegram\bot.py", line 332, in _message
    result = self._post(endpoint, data, timeout=timeout, api_kwargs=api_kwargs)
  File "D:\1_PT_START_2024.1\5_module\theory\venv\lib\site-packages\telegram\bot.py", line 295, in _post
    return self.request.post(
  File "D:\1_PT_START_2024.1\5_module\theory\venv\lib\site-packages\telegram\utils\request.py", line 356, in post
    result = self._request_wrapper(
  File "D:\1_PT_START_2024.1\5_module\theory\venv\lib\site-packages\telegram\utils\request.py", line 279, in _request_wrapper
    raise BadRequest(message)
telegram.error.BadRequest: Message text is empty
2024-05-09 14:24:25,549 - telegram.ext.updater - INFO - Received signal 2 (SIGINT), stopping...
2024-05-09 14:24:25,549 - apscheduler.scheduler - INFO - Scheduler has been shut down
2024-05-09 14:24:50,015 - apscheduler.scheduler - INFO - Scheduler started
2024-05-09 14:24:52,654 - paramiko.transport - INFO - Connected (version 2.0, client OpenSSH_9.2p1)
2024-05-09 14:24:52,792 - paramiko.transport - INFO - Authentication (publickey) failed.
2024-05-09 14:24:52,802 - paramiko.transport - INFO - Authentication (publickey) failed.
2024-05-09 14:24:52,874 - paramiko.transport - INFO - Authentication (password) successful!
2024-05-09 14:26:54,698 - telegram.ext.updater - INFO - Received signal 2 (SIGINT), stopping...
2024-05-09 14:26:54,699 - apscheduler.scheduler - INFO - Scheduler has been shut down
2024-05-09 14:26:58,512 - apscheduler.scheduler - INFO - Scheduler started
2024-05-09 14:27:44,025 - telegram.ext.updater - INFO - Received signal 2 (SIGINT), stopping...
2024-05-09 14:27:44,026 - apscheduler.scheduler - INFO - Scheduler has been shut down
2024-05-09 14:27:47,272 - apscheduler.scheduler - INFO - Scheduler started
2024-05-09 14:28:04,423 - paramiko.transport - INFO - Connected (version 2.0, client OpenSSH_9.2p1)
2024-05-09 14:28:04,562 - paramiko.transport - INFO - Authentication (publickey) failed.
2024-05-09 14:28:04,574 - paramiko.transport - INFO - Authentication (publickey) failed.
2024-05-09 14:28:04,611 - paramiko.transport - INFO - Authentication (password) successful!
2024-05-09 14:28:09,406 - paramiko.transport - INFO - Connected (version 2.0, client OpenSSH_9.2p1)
2024-05-09 14:28:09,546 - paramiko.transport - INFO - Authentication (publickey) failed.
2024-05-09 14:28:09,557 - paramiko.transport - INFO - Authentication (publickey) failed.
2024-05-09 14:28:09,594 - paramiko.transport - INFO - Authentication (password) successful!
2024-05-09 14:28:42,194 - telegram.ext.updater - INFO - Received signal 2 (SIGINT), stopping...
2024-05-09 14:28:42,194 - apscheduler.scheduler - INFO - Scheduler has been shut down
2024-05-09 14:29:09,401 - apscheduler.scheduler - INFO - Scheduler started
2024-05-09 14:30:15,674 - paramiko.transport - INFO - Connected (version 2.0, client OpenSSH_9.2p1)
2024-05-09 14:30:15,820 - paramiko.transport - INFO - Authentication (publickey) failed.
2024-05-09 14:30:15,830 - paramiko.transport - INFO - Authentication (publickey) failed.
2024-05-09 14:30:15,867 - paramiko.transport - INFO - Authentication (password) successful!
2024-05-09 14:30:18,262 - paramiko.transport - INFO - Connected (version 2.0, client OpenSSH_9.2p1)
2024-05-09 14:30:18,412 - paramiko.transport - INFO - Authentication (publickey) failed.
2024-05-09 14:30:18,423 - paramiko.transport - INFO - Authentication (publickey) failed.
2024-05-09 14:30:18,460 - paramiko.transport - INFO - Authentication (password) successful!
2024-05-09 14:30:20,103 - paramiko.transport - INFO - Connected (version 2.0, client OpenSSH_9.2p1)
2024-05-09 14:30:20,277 - paramiko.transport - INFO - Authentication (publickey) failed.
2024-05-09 14:30:20,288 - paramiko.transport - INFO - Authentication (publickey) failed.
2024-05-09 14:30:20,360 - paramiko.transport - INFO - Authentication (password) successful!
2024-05-09 14:30:38,270 - telegram.ext.dispatcher - ERROR - No error handlers are registered, logging exception.
Traceback (most recent call last):
  File "D:\1_PT_START_2024.1\5_module\theory\venv\lib\site-packages\telegram\ext\dispatcher.py", line 555, in process_update
    handler.handle_update(update, self, check, context)
  File "D:\1_PT_START_2024.1\5_module\theory\venv\lib\site-packages\telegram\ext\conversationhandler.py", line 626, in handle_update
    new_state = handler.handle_update(update, dispatcher, check_result, context)
  File "D:\1_PT_START_2024.1\5_module\theory\venv\lib\site-packages\telegram\ext\handler.py", line 198, in handle_update
    return self.callback(update, context)
  File "D:\1_PT_START_2024.1\5_module\practice_project\db_practice.py", line 71, in save_phone_numbers
    conn = psycopg2.connect(
  File "D:\1_PT_START_2024.1\5_module\theory\venv\lib\site-packages\psycopg2\__init__.py", line 122, in connect
    conn = _connect(dsn, connection_factory=connection_factory, **kwasync)
psycopg2.OperationalError: connection to server at "192.168.1.51", port 22 failed: server closed the connection unexpectedly
	This probably means the server terminated abnormally
	before or while processing the request.
SSL SYSCALL error: Connection reset by peer (0x00002746/10054)
connection to server at "192.168.1.51", port 22 failed: expected authentication request from server, but received S

2024-05-09 14:31:16,667 - telegram.ext.updater - INFO - Received signal 2 (SIGINT), stopping...
2024-05-09 14:31:16,668 - apscheduler.scheduler - INFO - Scheduler has been shut down
2024-05-09 14:31:21,050 - apscheduler.scheduler - INFO - Scheduler started
2024-05-09 14:31:36,623 - paramiko.transport - INFO - Connected (version 2.0, client OpenSSH_9.2p1)
2024-05-09 14:31:36,874 - paramiko.transport - INFO - Authentication (publickey) failed.
2024-05-09 14:31:36,885 - paramiko.transport - INFO - Authentication (publickey) failed.
2024-05-09 14:31:36,958 - paramiko.transport - INFO - Authentication (password) successful!
2024-05-09 14:37:20,421 - telegram.ext.updater - INFO - Received signal 2 (SIGINT), stopping...
2024-05-09 14:37:20,421 - apscheduler.scheduler - INFO - Scheduler has been shut down
2024-05-09 14:54:47,992 - apscheduler.scheduler - INFO - Scheduler started
2024-05-09 14:55:11,845 - paramiko.transport - INFO - Connected (version 2.0, client OpenSSH_9.2p1)
2024-05-09 14:55:11,982 - paramiko.transport - INFO - Authentication (publickey) failed.
2024-05-09 14:55:11,992 - paramiko.transport - INFO - Authentication (publickey) failed.
2024-05-09 14:55:12,029 - paramiko.transport - INFO - Authentication (password) successful!
2024-05-09 14:56:30,695 - paramiko.transport - INFO - Connected (version 2.0, client OpenSSH_9.2p1)
2024-05-09 14:56:30,875 - paramiko.transport - INFO - Authentication (publickey) failed.
2024-05-09 14:56:30,886 - paramiko.transport - INFO - Authentication (publickey) failed.
2024-05-09 14:56:30,923 - paramiko.transport - INFO - Authentication (password) successful!
2024-05-09 14:56:49,950 - paramiko.transport - INFO - Connected (version 2.0, client OpenSSH_9.2p1)
2024-05-09 14:56:50,086 - paramiko.transport - INFO - Authentication (publickey) failed.
2024-05-09 14:56:50,097 - paramiko.transport - INFO - Authentication (publickey) failed.
2024-05-09 14:56:50,134 - paramiko.transport - INFO - Authentication (password) successful!
2024-05-09 15:06:02,887 - paramiko.transport - INFO - Connected (version 2.0, client OpenSSH_9.2p1)
2024-05-09 15:06:03,024 - paramiko.transport - INFO - Authentication (publickey) failed.
2024-05-09 15:06:03,034 - paramiko.transport - INFO - Authentication (publickey) failed.
2024-05-09 15:06:03,071 - paramiko.transport - INFO - Authentication (password) successful!
2024-05-09 15:06:20,314 - paramiko.transport - INFO - Connected (version 2.0, client OpenSSH_9.2p1)
2024-05-09 15:06:20,446 - paramiko.transport - INFO - Authentication (publickey) failed.
2024-05-09 15:06:20,457 - paramiko.transport - INFO - Authentication (publickey) failed.
2024-05-09 15:06:20,493 - paramiko.transport - INFO - Authentication (password) successful!
2024-05-09 15:10:42,791 - paramiko.transport - INFO - Connected (version 2.0, client OpenSSH_9.2p1)
2024-05-09 15:10:42,931 - paramiko.transport - INFO - Authentication (publickey) failed.
2024-05-09 15:10:42,941 - paramiko.transport - INFO - Authentication (publickey) failed.
2024-05-09 15:10:42,978 - paramiko.transport - INFO - Authentication (password) successful!
2024-05-09 15:11:06,552 - paramiko.transport - INFO - Connected (version 2.0, client OpenSSH_9.2p1)
2024-05-09 15:11:06,688 - paramiko.transport - INFO - Authentication (publickey) failed.
2024-05-09 15:11:06,698 - paramiko.transport - INFO - Authentication (publickey) failed.
2024-05-09 15:11:06,735 - paramiko.transport - INFO - Authentication (password) successful!
2024-05-09 15:12:30,172 - telegram.ext.updater - INFO - Received signal 2 (SIGINT), stopping...
2024-05-09 15:12:30,172 - apscheduler.scheduler - INFO - Scheduler has been shut down
2024-05-09 15:12:40,789 - apscheduler.scheduler - INFO - Scheduler started
2024-05-09 15:12:46,140 - paramiko.transport - INFO - Connected (version 2.0, client OpenSSH_9.2p1)
2024-05-09 15:12:46,286 - paramiko.transport - INFO - Authentication (publickey) failed.
2024-05-09 15:12:46,297 - paramiko.transport - INFO - Authentication (publickey) failed.
2024-05-09 15:12:46,334 - paramiko.transport - INFO - Authentication (password) successful!
2024-05-09 15:13:51,247 - telegram.ext.updater - INFO - Received signal 2 (SIGINT), stopping...
2024-05-09 15:13:51,247 - apscheduler.scheduler - INFO - Scheduler has been shut down
2024-05-12 12:17:04,757 - apscheduler.scheduler - INFO - Scheduler started
2024-05-12 12:17:07,225 - paramiko.transport - INFO - Connected (version 2.0, client OpenSSH_9.2p1)
2024-05-12 12:17:07,376 - paramiko.transport - INFO - Authentication (publickey) failed.
2024-05-12 12:17:07,393 - paramiko.transport - INFO - Authentication (publickey) failed.
2024-05-12 12:17:07,466 - paramiko.transport - INFO - Authentication (password) successful!
2024-05-12 12:17:09,361 - paramiko.transport - INFO - Connected (version 2.0, client OpenSSH_9.2p1)
2024-05-12 12:17:09,503 - paramiko.transport - INFO - Authentication (publickey) failed.
2024-05-12 12:17:09,514 - paramiko.transport - INFO - Authentication (publickey) failed.
2024-05-12 12:17:09,581 - paramiko.transport - INFO - Authentication (password) successful!
2024-05-12 12:34:38,656 - telegram.ext.updater - INFO - Received signal 2 (SIGINT), stopping...
2024-05-12 12:34:38,656 - apscheduler.scheduler - INFO - Scheduler has been shut down
2024-05-12 06:16:16,114 - apscheduler.scheduler - INFO - Scheduler started
2024-05-12 06:16:16,785 - telegram.ext.dispatcher - ERROR - No error handlers are registered, logging exception.
Traceback (most recent call last):
  File "/usr/local/lib/python3.9/site-packages/telegram/ext/dispatcher.py", line 555, in process_update
    handler.handle_update(update, self, check, context)
  File "/usr/local/lib/python3.9/site-packages/telegram/ext/handler.py", line 198, in handle_update
    return self.callback(update, context)
  File "/app/db_practice.py", line 58, in get_phones
    response = execute_ssh_command(host, port, username, password, "psql -U postgres -d db_practice -c 'SELECT * FROM phones;'")
  File "/app/db_practice.py", line 42, in execute_ssh_command
    client.connect(hostname=host, port=port, username=username, password=password)
  File "/usr/local/lib/python3.9/site-packages/paramiko/client.py", line 409, in connect
    raise NoValidConnectionsError(errors)
paramiko.ssh_exception.NoValidConnectionsError: [Errno None] Unable to connect to port 22 on 127.0.0.1 or ::1
2024-05-12 06:16:26,761 - telegram.ext.dispatcher - ERROR - No error handlers are registered, logging exception.
Traceback (most recent call last):
  File "/usr/local/lib/python3.9/site-packages/telegram/ext/dispatcher.py", line 555, in process_update
    handler.handle_update(update, self, check, context)
  File "/usr/local/lib/python3.9/site-packages/telegram/ext/handler.py", line 198, in handle_update
    return self.callback(update, context)
  File "/app/db_practice.py", line 58, in get_phones
    response = execute_ssh_command(host, port, username, password, "psql -U postgres -d db_practice -c 'SELECT * FROM phones;'")
  File "/app/db_practice.py", line 42, in execute_ssh_command
    client.connect(hostname=host, port=port, username=username, password=password)
  File "/usr/local/lib/python3.9/site-packages/paramiko/client.py", line 409, in connect
    raise NoValidConnectionsError(errors)
paramiko.ssh_exception.NoValidConnectionsError: [Errno None] Unable to connect to port 22 on 127.0.0.1 or ::1
2024-05-12 07:25:18,196 - telegram.ext.updater - ERROR - Error while getting Updates: urllib3 HTTPError ('Connection aborted.', RemoteDisconnected('Remote end closed connection without response'))
2024-05-12 07:25:18,197 - telegram.ext.dispatcher - ERROR - No error handlers are registered, logging exception.
Traceback (most recent call last):
  File "/usr/local/lib/python3.9/site-packages/telegram/vendor/ptb_urllib3/urllib3/connectionpool.py", line 614, in urlopen
    httplib_response = self._make_request(conn, method, url,
  File "/usr/local/lib/python3.9/site-packages/telegram/vendor/ptb_urllib3/urllib3/connectionpool.py", line 402, in _make_request
    six.raise_from(e, None)
  File "<string>", line 2, in raise_from
  File "/usr/local/lib/python3.9/site-packages/telegram/vendor/ptb_urllib3/urllib3/connectionpool.py", line 398, in _make_request
    httplib_response = conn.getresponse()
  File "/usr/local/lib/python3.9/http/client.py", line 1377, in getresponse
    response.begin()
  File "/usr/local/lib/python3.9/http/client.py", line 320, in begin
    version, status, reason = self._read_status()
  File "/usr/local/lib/python3.9/http/client.py", line 289, in _read_status
    raise RemoteDisconnected("Remote end closed connection without"
http.client.RemoteDisconnected: Remote end closed connection without response

During handling of the above exception, another exception occurred:

Traceback (most recent call last):
  File "/usr/local/lib/python3.9/site-packages/telegram/utils/request.py", line 259, in _request_wrapper
    resp = self._con_pool.request(*args, **kwargs)
  File "/usr/local/lib/python3.9/site-packages/telegram/vendor/ptb_urllib3/urllib3/request.py", line 68, in request
    return self.request_encode_body(method, url, fields=fields,
  File "/usr/local/lib/python3.9/site-packages/telegram/vendor/ptb_urllib3/urllib3/request.py", line 148, in request_encode_body
    return self.urlopen(method, url, **extra_kw)
  File "/usr/local/lib/python3.9/site-packages/telegram/vendor/ptb_urllib3/urllib3/poolmanager.py", line 244, in urlopen
    response = conn.urlopen(method, u.request_uri, **kw)
  File "/usr/local/lib/python3.9/site-packages/telegram/vendor/ptb_urllib3/urllib3/connectionpool.py", line 665, in urlopen
    retries = retries.increment(method, url, error=e, _pool=self,
  File "/usr/local/lib/python3.9/site-packages/telegram/vendor/ptb_urllib3/urllib3/util/retry.py", line 347, in increment
    raise six.reraise(type(error), error, _stacktrace)
  File "/usr/local/lib/python3.9/site-packages/telegram/vendor/ptb_urllib3/urllib3/packages/six.py", line 685, in reraise
    raise value.with_traceback(tb)
  File "/usr/local/lib/python3.9/site-packages/telegram/vendor/ptb_urllib3/urllib3/connectionpool.py", line 614, in urlopen
    httplib_response = self._make_request(conn, method, url,
  File "/usr/local/lib/python3.9/site-packages/telegram/vendor/ptb_urllib3/urllib3/connectionpool.py", line 402, in _make_request
    six.raise_from(e, None)
  File "<string>", line 2, in raise_from
  File "/usr/local/lib/python3.9/site-packages/telegram/vendor/ptb_urllib3/urllib3/connectionpool.py", line 398, in _make_request
    httplib_response = conn.getresponse()
  File "/usr/local/lib/python3.9/http/client.py", line 1377, in getresponse
    response.begin()
  File "/usr/local/lib/python3.9/http/client.py", line 320, in begin
    version, status, reason = self._read_status()
  File "/usr/local/lib/python3.9/http/client.py", line 289, in _read_status
    raise RemoteDisconnected("Remote end closed connection without"
telegram.vendor.ptb_urllib3.urllib3.exceptions.ProtocolError: ('Connection aborted.', RemoteDisconnected('Remote end closed connection without response'))

The above exception was the direct cause of the following exception:

Traceback (most recent call last):
  File "/usr/local/lib/python3.9/site-packages/telegram/ext/updater.py", line 646, in _network_loop_retry
    if not action_cb():
  File "/usr/local/lib/python3.9/site-packages/telegram/ext/updater.py", line 597, in polling_action_cb
    updates = self.bot.get_updates(
  File "/usr/local/lib/python3.9/site-packages/telegram/ext/extbot.py", line 222, in get_updates
    updates = super().get_updates(
  File "/usr/local/lib/python3.9/site-packages/telegram/bot.py", line 130, in decorator
    result = func(*args, **kwargs)
  File "/usr/local/lib/python3.9/site-packages/telegram/bot.py", line 2861, in get_updates
    self._post(
  File "/usr/local/lib/python3.9/site-packages/telegram/bot.py", line 295, in _post
    return self.request.post(
  File "/usr/local/lib/python3.9/site-packages/telegram/utils/request.py", line 356, in post
    result = self._request_wrapper(
  File "/usr/local/lib/python3.9/site-packages/telegram/utils/request.py", line 265, in _request_wrapper
    raise NetworkError(f'urllib3 HTTPError {error}') from error
telegram.error.NetworkError: urllib3 HTTPError ('Connection aborted.', RemoteDisconnected('Remote end closed connection without response'))
2024-05-12 07:40:15,545 - telegram.ext.dispatcher - ERROR - No error handlers are registered, logging exception.
Traceback (most recent call last):
  File "/usr/local/lib/python3.9/site-packages/telegram/ext/dispatcher.py", line 555, in process_update
    handler.handle_update(update, self, check, context)
  File "/usr/local/lib/python3.9/site-packages/telegram/ext/handler.py", line 198, in handle_update
    return self.callback(update, context)
  File "/app/db_practice.py", line 58, in get_phones
    user=user,
  File "/app/db_practice.py", line 42, in execute_ssh_command
    #     client.connect(hostname=host, port=port, username=username, password=password)
  File "/usr/local/lib/python3.9/site-packages/paramiko/client.py", line 409, in connect
    raise NoValidConnectionsError(errors)
paramiko.ssh_exception.NoValidConnectionsError: [Errno None] Unable to connect to port 22 on 127.0.0.1 or ::1
2024-05-12 07:40:37,618 - telegram.ext.updater - INFO - Received signal 15 (SIGTERM), stopping...
2024-05-12 07:40:37,619 - apscheduler.scheduler - INFO - Scheduler has been shut down
2024-05-12 07:40:58,275 - apscheduler.scheduler - INFO - Scheduler started
2024-05-12 07:41:02,719 - telegram.ext.dispatcher - ERROR - No error handlers are registered, logging exception.
Traceback (most recent call last):
  File "/usr/local/lib/python3.9/site-packages/telegram/ext/dispatcher.py", line 555, in process_update
    handler.handle_update(update, self, check, context)
  File "/usr/local/lib/python3.9/site-packages/telegram/ext/handler.py", line 198, in handle_update
    return self.callback(update, context)
  File "/app/db_practice.py", line 81, in get_phones
    response = execute_sql_command(host, db_port, username, password, "SELECT * FROM phones;")
TypeError: execute_sql_command() missing 1 required positional argument: 'sql_command'
2024-05-12 07:42:26,760 - telegram.ext.dispatcher - ERROR - No error handlers are registered, logging exception.
Traceback (most recent call last):
  File "/usr/local/lib/python3.9/site-packages/telegram/ext/dispatcher.py", line 555, in process_update
    handler.handle_update(update, self, check, context)
  File "/usr/local/lib/python3.9/site-packages/telegram/ext/handler.py", line 198, in handle_update
    return self.callback(update, context)
  File "/app/db_practice.py", line 81, in get_phones
    response = execute_sql_command(host, db_port dbname, username, password, "SELECT * FROM phones;")
TypeError: execute_sql_command() missing 1 required positional argument: 'sql_command'
2024-05-12 07:42:51,926 - telegram.ext.dispatcher - ERROR - No error handlers are registered, logging exception.
Traceback (most recent call last):
  File "/usr/local/lib/python3.9/site-packages/telegram/ext/dispatcher.py", line 555, in process_update
    handler.handle_update(update, self, check, context)
  File "/usr/local/lib/python3.9/site-packages/telegram/ext/handler.py", line 198, in handle_update
    return self.callback(update, context)
  File "/app/db_practice.py", line 81, in get_phones
    response = execute_sql_command(host, db_port dbname, username, password, "SELECT * FROM phones;")
TypeError: execute_sql_command() missing 1 required positional argument: 'sql_command'
2024-05-12 07:42:57,262 - telegram.ext.updater - INFO - Received signal 15 (SIGTERM), stopping...
2024-05-12 07:42:57,262 - apscheduler.scheduler - INFO - Scheduler has been shut down
2024-05-12 07:44:03,360 - apscheduler.scheduler - INFO - Scheduler started
2024-05-12 07:44:04,465 - telegram.ext.dispatcher - ERROR - No error handlers are registered, logging exception.
Traceback (most recent call last):
  File "/usr/local/lib/python3.9/site-packages/telegram/ext/dispatcher.py", line 555, in process_update
    handler.handle_update(update, self, check, context)
  File "/usr/local/lib/python3.9/site-packages/telegram/ext/handler.py", line 198, in handle_update
    return self.callback(update, context)
  File "/app/db_practice.py", line 82, in get_phones
    update.message.reply_text(response)
  File "/usr/local/lib/python3.9/site-packages/telegram/message.py", line 764, in reply_text
    return self.bot.send_message(
  File "/usr/local/lib/python3.9/site-packages/telegram/bot.py", line 130, in decorator
    result = func(*args, **kwargs)
  File "/usr/local/lib/python3.9/site-packages/telegram/bot.py", line 513, in send_message
    return self._message(  # type: ignore[return-value]
  File "/usr/local/lib/python3.9/site-packages/telegram/ext/extbot.py", line 199, in _message
    result = super()._message(
  File "/usr/local/lib/python3.9/site-packages/telegram/bot.py", line 332, in _message
    result = self._post(endpoint, data, timeout=timeout, api_kwargs=api_kwargs)
  File "/usr/local/lib/python3.9/site-packages/telegram/bot.py", line 295, in _post
    return self.request.post(
  File "/usr/local/lib/python3.9/site-packages/telegram/utils/request.py", line 356, in post
    result = self._request_wrapper(
  File "/usr/local/lib/python3.9/site-packages/telegram/utils/request.py", line 279, in _request_wrapper
    raise BadRequest(message)
telegram.error.BadRequest: Message text is empty
2024-05-12 07:44:07,581 - telegram.ext.updater - INFO - Received signal 15 (SIGTERM), stopping...
2024-05-12 07:44:07,582 - apscheduler.scheduler - INFO - Scheduler has been shut down
2024-05-12 07:44:19,072 - apscheduler.scheduler - INFO - Scheduler started
2024-05-12 07:44:40,528 - telegram.ext.dispatcher - ERROR - No error handlers are registered, logging exception.
Traceback (most recent call last):
  File "/usr/local/lib/python3.9/site-packages/telegram/ext/dispatcher.py", line 555, in process_update
    handler.handle_update(update, self, check, context)
  File "/usr/local/lib/python3.9/site-packages/telegram/ext/handler.py", line 198, in handle_update
    return self.callback(update, context)
  File "/app/db_practice.py", line 82, in get_phones
    update.message.reply_text(response)
  File "/usr/local/lib/python3.9/site-packages/telegram/message.py", line 764, in reply_text
    return self.bot.send_message(
  File "/usr/local/lib/python3.9/site-packages/telegram/bot.py", line 130, in decorator
    result = func(*args, **kwargs)
  File "/usr/local/lib/python3.9/site-packages/telegram/bot.py", line 513, in send_message
    return self._message(  # type: ignore[return-value]
  File "/usr/local/lib/python3.9/site-packages/telegram/ext/extbot.py", line 199, in _message
    result = super()._message(
  File "/usr/local/lib/python3.9/site-packages/telegram/bot.py", line 332, in _message
    result = self._post(endpoint, data, timeout=timeout, api_kwargs=api_kwargs)
  File "/usr/local/lib/python3.9/site-packages/telegram/bot.py", line 295, in _post
    return self.request.post(
  File "/usr/local/lib/python3.9/site-packages/telegram/utils/request.py", line 356, in post
    result = self._request_wrapper(
  File "/usr/local/lib/python3.9/site-packages/telegram/utils/request.py", line 279, in _request_wrapper
    raise BadRequest(message)
telegram.error.BadRequest: Message text is empty
2024-05-12 07:46:03,110 - telegram.ext.dispatcher - ERROR - No error handlers are registered, logging exception.
Traceback (most recent call last):
  File "/usr/local/lib/python3.9/site-packages/telegram/ext/dispatcher.py", line 555, in process_update
    handler.handle_update(update, self, check, context)
  File "/usr/local/lib/python3.9/site-packages/telegram/ext/handler.py", line 198, in handle_update
    return self.callback(update, context)
  File "/app/db_practice.py", line 82, in get_phones
    update.message.reply_text(str(response))
  File "/usr/local/lib/python3.9/site-packages/telegram/message.py", line 764, in reply_text
    return self.bot.send_message(
  File "/usr/local/lib/python3.9/site-packages/telegram/bot.py", line 130, in decorator
    result = func(*args, **kwargs)
  File "/usr/local/lib/python3.9/site-packages/telegram/bot.py", line 513, in send_message
    return self._message(  # type: ignore[return-value]
  File "/usr/local/lib/python3.9/site-packages/telegram/ext/extbot.py", line 199, in _message
    result = super()._message(
  File "/usr/local/lib/python3.9/site-packages/telegram/bot.py", line 332, in _message
    result = self._post(endpoint, data, timeout=timeout, api_kwargs=api_kwargs)
  File "/usr/local/lib/python3.9/site-packages/telegram/bot.py", line 295, in _post
    return self.request.post(
  File "/usr/local/lib/python3.9/site-packages/telegram/utils/request.py", line 356, in post
    result = self._request_wrapper(
  File "/usr/local/lib/python3.9/site-packages/telegram/utils/request.py", line 279, in _request_wrapper
    raise BadRequest(message)
telegram.error.BadRequest: Message text is empty
2024-05-12 07:46:30,754 - telegram.ext.updater - INFO - Received signal 15 (SIGTERM), stopping...
2024-05-12 07:46:30,755 - apscheduler.scheduler - INFO - Scheduler has been shut down
2024-05-12 07:46:37,095 - apscheduler.scheduler - INFO - Scheduler started
2024-05-12 07:52:26,810 - telegram.ext.updater - INFO - Received signal 15 (SIGTERM), stopping...
2024-05-12 07:52:26,810 - apscheduler.scheduler - INFO - Scheduler has been shut down
2024-05-12 07:52:51,653 - apscheduler.scheduler - INFO - Scheduler started
2024-05-12 07:59:29,631 - telegram.ext.updater - INFO - Received signal 15 (SIGTERM), stopping...
2024-05-12 07:59:29,632 - apscheduler.scheduler - INFO - Scheduler has been shut down
2024-05-12 08:02:03,510 - apscheduler.scheduler - INFO - Scheduler started
2024-05-12 08:06:45,549 - telegram.ext.updater - INFO - Received signal 15 (SIGTERM), stopping...
2024-05-12 08:06:45,549 - apscheduler.scheduler - INFO - Scheduler has been shut down
2024-05-12 08:06:52,246 - apscheduler.scheduler - INFO - Scheduler started
2024-05-12 08:07:21,429 - telegram.ext.updater - INFO - Received signal 15 (SIGTERM), stopping...
2024-05-12 08:07:21,430 - apscheduler.scheduler - INFO - Scheduler has been shut down
2024-05-12 08:07:28,390 - apscheduler.scheduler - INFO - Scheduler started
2024-05-12 08:07:30,995 - telegram.ext.dispatcher - ERROR - No error handlers are registered, logging exception.
Traceback (most recent call last):
  File "/usr/local/lib/python3.9/site-packages/telegram/ext/dispatcher.py", line 555, in process_update
    handler.handle_update(update, self, check, context)
  File "/usr/local/lib/python3.9/site-packages/telegram/ext/handler.py", line 198, in handle_update
    return self.callback(update, context)
  File "/app/db_practice.py", line 111, in get_phones
    update.message.reply_text(response)
  File "/usr/local/lib/python3.9/site-packages/telegram/message.py", line 764, in reply_text
    return self.bot.send_message(
  File "/usr/local/lib/python3.9/site-packages/telegram/bot.py", line 130, in decorator
    result = func(*args, **kwargs)
  File "/usr/local/lib/python3.9/site-packages/telegram/bot.py", line 513, in send_message
    return self._message(  # type: ignore[return-value]
  File "/usr/local/lib/python3.9/site-packages/telegram/ext/extbot.py", line 199, in _message
    result = super()._message(
  File "/usr/local/lib/python3.9/site-packages/telegram/bot.py", line 332, in _message
    result = self._post(endpoint, data, timeout=timeout, api_kwargs=api_kwargs)
  File "/usr/local/lib/python3.9/site-packages/telegram/bot.py", line 295, in _post
    return self.request.post(
  File "/usr/local/lib/python3.9/site-packages/telegram/utils/request.py", line 356, in post
    result = self._request_wrapper(
  File "/usr/local/lib/python3.9/site-packages/telegram/utils/request.py", line 279, in _request_wrapper
    raise BadRequest(message)
telegram.error.BadRequest: Message text is empty
2024-05-12 08:13:53,372 - telegram.ext.dispatcher - ERROR - No error handlers are registered, logging exception.
Traceback (most recent call last):
  File "/usr/local/lib/python3.9/site-packages/telegram/ext/dispatcher.py", line 555, in process_update
    handler.handle_update(update, self, check, context)
  File "/usr/local/lib/python3.9/site-packages/telegram/ext/handler.py", line 198, in handle_update
    return self.callback(update, context)
  File "/app/db_practice.py", line 111, in get_phones
    def get_phones(update: Update, context: CallbackContext):
  File "/usr/local/lib/python3.9/site-packages/telegram/message.py", line 764, in reply_text
    return self.bot.send_message(
  File "/usr/local/lib/python3.9/site-packages/telegram/bot.py", line 130, in decorator
    result = func(*args, **kwargs)
  File "/usr/local/lib/python3.9/site-packages/telegram/bot.py", line 513, in send_message
    return self._message(  # type: ignore[return-value]
  File "/usr/local/lib/python3.9/site-packages/telegram/ext/extbot.py", line 199, in _message
    result = super()._message(
  File "/usr/local/lib/python3.9/site-packages/telegram/bot.py", line 332, in _message
    result = self._post(endpoint, data, timeout=timeout, api_kwargs=api_kwargs)
  File "/usr/local/lib/python3.9/site-packages/telegram/bot.py", line 295, in _post
    return self.request.post(
  File "/usr/local/lib/python3.9/site-packages/telegram/utils/request.py", line 356, in post
    result = self._request_wrapper(
  File "/usr/local/lib/python3.9/site-packages/telegram/utils/request.py", line 279, in _request_wrapper
    raise BadRequest(message)
telegram.error.BadRequest: Message text is empty
2024-05-12 08:14:12,353 - telegram.ext.updater - INFO - Received signal 15 (SIGTERM), stopping...
2024-05-12 08:14:12,354 - apscheduler.scheduler - INFO - Scheduler has been shut down
2024-05-12 08:14:43,838 - apscheduler.scheduler - INFO - Scheduler started
2024-05-12 08:15:53,774 - telegram.ext.dispatcher - ERROR - No error handlers are registered, logging exception.
Traceback (most recent call last):
  File "/usr/local/lib/python3.9/site-packages/telegram/ext/dispatcher.py", line 555, in process_update
    handler.handle_update(update, self, check, context)
  File "/usr/local/lib/python3.9/site-packages/telegram/ext/conversationhandler.py", line 626, in handle_update
    new_state = handler.handle_update(update, dispatcher, check_result, context)
  File "/usr/local/lib/python3.9/site-packages/telegram/ext/handler.py", line 198, in handle_update
    return self.callback(update, context)
  File "/app/db_practice.py", line 126, in save_emails
    conn = psycopg2.connect(
  File "/usr/local/lib/python3.9/site-packages/psycopg2/__init__.py", line 122, in connect
    conn = _connect(dsn, connection_factory=connection_factory, **kwasync)
psycopg2.OperationalError: connection to server at "localhost" (::1), port 5432 failed: Connection refused
	Is the server running on that host and accepting TCP/IP connections?
connection to server at "localhost" (127.0.0.1), port 5432 failed: Connection refused
	Is the server running on that host and accepting TCP/IP connections?

2024-05-12 08:23:54,175 - telegram.ext.updater - INFO - Received signal 15 (SIGTERM), stopping...
2024-05-12 08:23:54,176 - apscheduler.scheduler - INFO - Scheduler has been shut down
2024-05-12 08:24:04,558 - apscheduler.scheduler - INFO - Scheduler started
2024-05-12 08:25:54,572 - telegram.ext.updater - INFO - Received signal 15 (SIGTERM), stopping...
2024-05-12 08:25:54,573 - apscheduler.scheduler - INFO - Scheduler has been shut down
2024-05-12 08:26:05,367 - apscheduler.scheduler - INFO - Scheduler started
2024-05-12 08:26:07,202 - telegram.ext.dispatcher - ERROR - No error handlers are registered, logging exception.
Traceback (most recent call last):
  File "/usr/local/lib/python3.9/site-packages/telegram/ext/dispatcher.py", line 555, in process_update
    handler.handle_update(update, self, check, context)
  File "/usr/local/lib/python3.9/site-packages/telegram/ext/handler.py", line 198, in handle_update
    return self.callback(update, context)
  File "/app/db_practice.py", line 114, in get_phones
    update.message.reply_text(response)
  File "/usr/local/lib/python3.9/site-packages/telegram/message.py", line 764, in reply_text
    return self.bot.send_message(
  File "/usr/local/lib/python3.9/site-packages/telegram/bot.py", line 130, in decorator
    result = func(*args, **kwargs)
  File "/usr/local/lib/python3.9/site-packages/telegram/bot.py", line 513, in send_message
    return self._message(  # type: ignore[return-value]
  File "/usr/local/lib/python3.9/site-packages/telegram/ext/extbot.py", line 199, in _message
    result = super()._message(
  File "/usr/local/lib/python3.9/site-packages/telegram/bot.py", line 332, in _message
    result = self._post(endpoint, data, timeout=timeout, api_kwargs=api_kwargs)
  File "/usr/local/lib/python3.9/site-packages/telegram/bot.py", line 295, in _post
    return self.request.post(
  File "/usr/local/lib/python3.9/site-packages/telegram/utils/request.py", line 356, in post
    result = self._request_wrapper(
  File "/usr/local/lib/python3.9/site-packages/telegram/utils/request.py", line 279, in _request_wrapper
    raise BadRequest(message)
telegram.error.BadRequest: Message text is empty
2024-05-12 08:30:00,645 - telegram.ext.dispatcher - ERROR - No error handlers are registered, logging exception.
Traceback (most recent call last):
  File "/usr/local/lib/python3.9/site-packages/telegram/ext/dispatcher.py", line 555, in process_update
    handler.handle_update(update, self, check, context)
  File "/usr/local/lib/python3.9/site-packages/telegram/ext/handler.py", line 198, in handle_update
    return self.callback(update, context)
  File "/app/db_practice.py", line 114, in get_phones
    update.message.reply_text(response)
  File "/usr/local/lib/python3.9/site-packages/telegram/message.py", line 764, in reply_text
    return self.bot.send_message(
  File "/usr/local/lib/python3.9/site-packages/telegram/bot.py", line 130, in decorator
    result = func(*args, **kwargs)
  File "/usr/local/lib/python3.9/site-packages/telegram/bot.py", line 513, in send_message
    return self._message(  # type: ignore[return-value]
  File "/usr/local/lib/python3.9/site-packages/telegram/ext/extbot.py", line 199, in _message
    result = super()._message(
  File "/usr/local/lib/python3.9/site-packages/telegram/bot.py", line 332, in _message
    result = self._post(endpoint, data, timeout=timeout, api_kwargs=api_kwargs)
  File "/usr/local/lib/python3.9/site-packages/telegram/bot.py", line 295, in _post
    return self.request.post(
  File "/usr/local/lib/python3.9/site-packages/telegram/utils/request.py", line 356, in post
    result = self._request_wrapper(
  File "/usr/local/lib/python3.9/site-packages/telegram/utils/request.py", line 279, in _request_wrapper
    raise BadRequest(message)
telegram.error.BadRequest: Message text is empty
2024-05-12 08:34:00,975 - telegram.ext.dispatcher - ERROR - No error handlers are registered, logging exception.
Traceback (most recent call last):
  File "/usr/local/lib/python3.9/site-packages/telegram/ext/dispatcher.py", line 555, in process_update
    handler.handle_update(update, self, check, context)
  File "/usr/local/lib/python3.9/site-packages/telegram/ext/handler.py", line 198, in handle_update
    return self.callback(update, context)
  File "/app/db_practice.py", line 114, in get_phones
    update.message.reply_text(response)
  File "/usr/local/lib/python3.9/site-packages/telegram/message.py", line 764, in reply_text
    return self.bot.send_message(
  File "/usr/local/lib/python3.9/site-packages/telegram/bot.py", line 130, in decorator
    result = func(*args, **kwargs)
  File "/usr/local/lib/python3.9/site-packages/telegram/bot.py", line 513, in send_message
    return self._message(  # type: ignore[return-value]
  File "/usr/local/lib/python3.9/site-packages/telegram/ext/extbot.py", line 199, in _message
    result = super()._message(
  File "/usr/local/lib/python3.9/site-packages/telegram/bot.py", line 332, in _message
    result = self._post(endpoint, data, timeout=timeout, api_kwargs=api_kwargs)
  File "/usr/local/lib/python3.9/site-packages/telegram/bot.py", line 295, in _post
    return self.request.post(
  File "/usr/local/lib/python3.9/site-packages/telegram/utils/request.py", line 356, in post
    result = self._request_wrapper(
  File "/usr/local/lib/python3.9/site-packages/telegram/utils/request.py", line 279, in _request_wrapper
    raise BadRequest(message)
telegram.error.BadRequest: Message text is empty
2024-05-12 08:38:52,023 - telegram.ext.updater - INFO - Received signal 15 (SIGTERM), stopping...
2024-05-12 08:38:52,024 - apscheduler.scheduler - INFO - Scheduler has been shut down
2024-05-12 08:53:49,269 - apscheduler.scheduler - INFO - Scheduler started
2024-05-12 08:53:57,403 - telegram.ext.dispatcher - ERROR - No error handlers are registered, logging exception.
Traceback (most recent call last):
  File "/usr/local/lib/python3.9/site-packages/telegram/ext/dispatcher.py", line 555, in process_update
    handler.handle_update(update, self, check, context)
  File "/usr/local/lib/python3.9/site-packages/telegram/ext/handler.py", line 198, in handle_update
    return self.callback(update, context)
  File "/app/db_practice.py", line 114, in get_phones
    update.message.reply_text(response)
  File "/usr/local/lib/python3.9/site-packages/telegram/message.py", line 764, in reply_text
    return self.bot.send_message(
  File "/usr/local/lib/python3.9/site-packages/telegram/bot.py", line 130, in decorator
    result = func(*args, **kwargs)
  File "/usr/local/lib/python3.9/site-packages/telegram/bot.py", line 513, in send_message
    return self._message(  # type: ignore[return-value]
  File "/usr/local/lib/python3.9/site-packages/telegram/ext/extbot.py", line 199, in _message
    result = super()._message(
  File "/usr/local/lib/python3.9/site-packages/telegram/bot.py", line 332, in _message
    result = self._post(endpoint, data, timeout=timeout, api_kwargs=api_kwargs)
  File "/usr/local/lib/python3.9/site-packages/telegram/bot.py", line 295, in _post
    return self.request.post(
  File "/usr/local/lib/python3.9/site-packages/telegram/utils/request.py", line 356, in post
    result = self._request_wrapper(
  File "/usr/local/lib/python3.9/site-packages/telegram/utils/request.py", line 279, in _request_wrapper
    raise BadRequest(message)
telegram.error.BadRequest: Message text is empty
2024-05-12 08:55:10,039 - telegram.ext.updater - INFO - Received signal 15 (SIGTERM), stopping...
2024-05-12 08:55:10,040 - apscheduler.scheduler - INFO - Scheduler has been shut down
2024-05-12 08:55:21,948 - apscheduler.scheduler - INFO - Scheduler started
2024-05-12 08:55:46,557 - telegram.ext.updater - INFO - Received signal 15 (SIGTERM), stopping...
2024-05-12 08:55:46,557 - apscheduler.scheduler - INFO - Scheduler has been shut down
2024-05-12 11:57:57,312 - apscheduler.scheduler - INFO - Scheduler started
2024-05-12 12:01:04,213 - telegram.ext.updater - INFO - Received signal 15 (SIGTERM), stopping...
2024-05-12 12:01:04,214 - apscheduler.scheduler - INFO - Scheduler has been shut down
2024-05-15 05:31:54,081 - apscheduler.scheduler - INFO - Scheduler started
2024-05-15 05:32:37,989 - telegram.ext.updater - INFO - Received signal 15 (SIGTERM), stopping...
2024-05-15 05:32:37,990 - apscheduler.scheduler - INFO - Scheduler has been shut down
2024-05-15 05:38:00,117 - apscheduler.scheduler - INFO - Scheduler started
2024-05-15 05:38:40,000 - telegram.ext.updater - INFO - Received signal 15 (SIGTERM), stopping...
2024-05-15 05:38:40,000 - apscheduler.scheduler - INFO - Scheduler has been shut down
2024-05-15 05:52:48,427 - apscheduler.scheduler - INFO - Scheduler started
2024-05-15 05:53:04,171 - telegram.ext.updater - INFO - Received signal 15 (SIGTERM), stopping...
2024-05-15 05:53:04,172 - apscheduler.scheduler - INFO - Scheduler has been shut down
2024-05-15 05:53:32,832 - apscheduler.scheduler - INFO - Scheduler started
2024-05-15 05:53:41,848 - telegram.ext.updater - INFO - Received signal 15 (SIGTERM), stopping...
2024-05-15 05:53:41,848 - apscheduler.scheduler - INFO - Scheduler has been shut down
2024-05-15 05:59:35,134 - apscheduler.scheduler - INFO - Scheduler started
2024-05-15 05:59:43,825 - telegram.ext.updater - INFO - Received signal 15 (SIGTERM), stopping...
2024-05-15 05:59:43,826 - apscheduler.scheduler - INFO - Scheduler has been shut down
2024-05-15 06:18:36,382 - apscheduler.scheduler - INFO - Scheduler started
2024-05-15 06:55:38,589 - telegram.ext.updater - INFO - Received signal 15 (SIGTERM), stopping...
2024-05-15 06:55:38,590 - apscheduler.scheduler - INFO - Scheduler has been shut down
2024-05-15 06:55:55,200 - apscheduler.scheduler - INFO - Scheduler started
2024-05-15 06:59:14,895 - telegram.ext.updater - INFO - Received signal 15 (SIGTERM), stopping...
2024-05-15 06:59:14,895 - apscheduler.scheduler - INFO - Scheduler has been shut down
2024-05-15 06:59:31,916 - apscheduler.scheduler - INFO - Scheduler started
2024-05-15 07:00:56,709 - telegram.ext.updater - INFO - Received signal 15 (SIGTERM), stopping...
2024-05-15 07:00:56,709 - apscheduler.scheduler - INFO - Scheduler has been shut down
2024-05-15 07:01:49,249 - apscheduler.scheduler - INFO - Scheduler started
2024-05-15 07:04:24,222 - telegram.ext.updater - INFO - Received signal 15 (SIGTERM), stopping...
2024-05-15 07:04:24,223 - apscheduler.scheduler - INFO - Scheduler has been shut down
2024-05-15 07:05:10,102 - apscheduler.scheduler - INFO - Scheduler started
2024-05-15 07:08:30,839 - telegram.ext.updater - INFO - Received signal 15 (SIGTERM), stopping...
2024-05-15 07:08:30,840 - apscheduler.scheduler - INFO - Scheduler has been shut down
2024-05-15 07:24:54,809 - apscheduler.scheduler - INFO - Scheduler started
2024-05-15 07:33:47,695 - telegram.ext.updater - INFO - Received signal 15 (SIGTERM), stopping...
2024-05-15 07:33:47,696 - apscheduler.scheduler - INFO - Scheduler has been shut down
2024-05-18 10:02:37,536 - apscheduler.scheduler - INFO - Scheduler started
2024-05-18 10:03:09,907 - telegram.ext.dispatcher - ERROR - No error handlers are registered, logging exception.
Traceback (most recent call last):
  File "/usr/local/lib/python3.9/site-packages/telegram/ext/dispatcher.py", line 555, in process_update
    handler.handle_update(update, self, check, context)
  File "/usr/local/lib/python3.9/site-packages/telegram/ext/handler.py", line 198, in handle_update
    return self.callback(update, context)
  File "/bot/monitoring.py", line 24, in get_release
    response = execute_ssh_command(host, port, username, password, "cat /etc/*-release")
  File "/bot/monitoring.py", line 14, in execute_ssh_command
    client.connect(hostname=host, port=port, username=username, password=password)
  File "/usr/local/lib/python3.9/site-packages/paramiko/client.py", line 409, in connect
    raise NoValidConnectionsError(errors)
paramiko.ssh_exception.NoValidConnectionsError: [Errno None] Unable to connect to port 22 on 192.168.1.51
2024-05-18 10:06:56,661 - telegram.ext.updater - INFO - Received signal 15 (SIGTERM), stopping...
2024-05-18 10:06:56,663 - apscheduler.scheduler - INFO - Scheduler has been shut down
2024-05-18 10:31:26,801 - apscheduler.scheduler - INFO - Scheduler started
2024-05-18 10:31:36,481 - monitoring - INFO - /get_release command executed by
2024-05-18 10:31:36,499 - paramiko.transport - INFO - Connected (version 2.0, client OpenSSH_9.6p1)
2024-05-18 10:31:36,620 - paramiko.transport - INFO - Authentication (password) successful!
2024-05-18 10:31:41,342 - monitoring - INFO - /get_release command executed by
2024-05-18 10:31:41,356 - paramiko.transport - INFO - Connected (version 2.0, client OpenSSH_9.6p1)
2024-05-18 10:31:41,475 - paramiko.transport - INFO - Authentication (password) successful!
2024-05-18 10:31:43,630 - paramiko.transport - INFO - Connected (version 2.0, client OpenSSH_9.6p1)
2024-05-18 10:31:43,749 - paramiko.transport - INFO - Authentication (password) successful!
2024-05-18 10:31:46,771 - paramiko.transport - INFO - Connected (version 2.0, client OpenSSH_9.6p1)
2024-05-18 10:31:46,837 - paramiko.transport - INFO - Authentication (password) successful!
2024-05-18 10:32:11,228 - paramiko.transport - INFO - Connected (version 2.0, client OpenSSH_9.6p1)
2024-05-18 10:32:11,294 - paramiko.transport - INFO - Authentication (password) successful!
2024-05-18 10:32:13,914 - paramiko.transport - INFO - Connected (version 2.0, client OpenSSH_9.6p1)
2024-05-18 10:32:13,980 - paramiko.transport - INFO - Authentication (password) successful!
2024-05-18 10:32:17,857 - paramiko.transport - INFO - Connected (version 2.0, client OpenSSH_9.6p1)
2024-05-18 10:32:17,979 - paramiko.transport - INFO - Authentication (password) successful!
2024-05-18 10:32:21,446 - paramiko.transport - INFO - Connected (version 2.0, client OpenSSH_9.6p1)
2024-05-18 10:32:21,525 - paramiko.transport - INFO - Authentication (password) successful!
2024-05-18 10:32:24,759 - paramiko.transport - INFO - Connected (version 2.0, client OpenSSH_9.6p1)
2024-05-18 10:32:24,824 - paramiko.transport - INFO - Authentication (password) successful!
2024-05-18 10:32:36,526 - paramiko.transport - INFO - Connected (version 2.0, client OpenSSH_9.6p1)
2024-05-18 10:32:36,595 - paramiko.transport - INFO - Authentication (password) successful!
2024-05-18 10:32:38,524 - paramiko.transport - INFO - Connected (version 2.0, client OpenSSH_9.6p1)
2024-05-18 10:32:38,587 - paramiko.transport - INFO - Authentication (password) successful!
2024-05-18 10:32:42,197 - paramiko.transport - INFO - Connected (version 2.0, client OpenSSH_9.6p1)
2024-05-18 10:32:42,278 - paramiko.transport - INFO - Authentication (password) successful!
2024-05-18 10:32:46,570 - paramiko.transport - INFO - Connected (version 2.0, client OpenSSH_9.6p1)
2024-05-18 10:32:46,639 - paramiko.transport - INFO - Authentication (password) successful!
2024-05-18 10:32:53,718 - paramiko.transport - INFO - Connected (version 2.0, client OpenSSH_9.6p1)
2024-05-18 10:32:53,783 - paramiko.transport - INFO - Authentication (password) successful!
2024-05-18 10:33:10,697 - telegram.ext.updater - INFO - Received signal 15 (SIGTERM), stopping...
2024-05-18 10:33:10,697 - apscheduler.scheduler - INFO - Scheduler has been shut down
2024-05-18 11:21:40,730 - apscheduler.scheduler - INFO - Scheduler started
2024-05-18 11:22:38,350 - monitoring - INFO - /get_release command executed by
2024-05-18 11:22:38,367 - paramiko.transport - INFO - Connected (version 2.0, client OpenSSH_9.6p1)
2024-05-18 11:22:38,499 - paramiko.transport - INFO - Authentication (password) successful!
2024-05-18 11:22:42,564 - telegram.ext.dispatcher - ERROR - No error handlers are registered, logging exception.
Traceback (most recent call last):
  File "/usr/local/lib/python3.9/site-packages/telegram/ext/dispatcher.py", line 555, in process_update
    handler.handle_update(update, self, check, context)
  File "/usr/local/lib/python3.9/site-packages/telegram/ext/handler.py", line 198, in handle_update
    return self.callback(update, context)
  File "/bot/db_practice.py", line 120, in get_emails
    response = execute_sql_command(host, db_port, dbname, username, password, "SELECT * FROM emails;")
NameError: name 'host' is not defined
2024-05-18 11:46:07,557 - telegram.ext.dispatcher - ERROR - No error handlers are registered, logging exception.
Traceback (most recent call last):
  File "/usr/local/lib/python3.9/site-packages/telegram/ext/dispatcher.py", line 555, in process_update
    handler.handle_update(update, self, check, context)
  File "/usr/local/lib/python3.9/site-packages/telegram/ext/handler.py", line 198, in handle_update
    return self.callback(update, context)
  File "/bot/db_practice.py", line 120, in get_emails
    response = execute_sql_command(host, db_port, dbname, username, password, "SELECT * FROM emails;")
NameError: name 'host' is not defined
2024-05-18 11:46:20,301 - telegram.ext.dispatcher - ERROR - No error handlers are registered, logging exception.
Traceback (most recent call last):
  File "/usr/local/lib/python3.9/site-packages/telegram/ext/dispatcher.py", line 555, in process_update
    handler.handle_update(update, self, check, context)
  File "/usr/local/lib/python3.9/site-packages/telegram/ext/handler.py", line 198, in handle_update
    return self.callback(update, context)
  File "/bot/db_practice.py", line 120, in get_emails
    response = execute_sql_command(host, db_port, dbname, username, password, "SELECT * FROM emails;")
NameError: name 'host' is not defined
2024-05-18 11:46:24,163 - monitoring - INFO - /get_release command executed by
2024-05-18 11:46:24,178 - paramiko.transport - INFO - Connected (version 2.0, client OpenSSH_9.6p1)
2024-05-18 11:46:24,295 - paramiko.transport - INFO - Authentication (password) successful!
2024-05-18 11:47:03,416 - telegram.ext.dispatcher - ERROR - No error handlers are registered, logging exception.
Traceback (most recent call last):
  File "/usr/local/lib/python3.9/site-packages/telegram/ext/dispatcher.py", line 555, in process_update
    handler.handle_update(update, self, check, context)
  File "/usr/local/lib/python3.9/site-packages/telegram/ext/conversationhandler.py", line 626, in handle_update
    new_state = handler.handle_update(update, dispatcher, check_result, context)
  File "/usr/local/lib/python3.9/site-packages/telegram/ext/handler.py", line 198, in handle_update
    return self.callback(update, context)
  File "/bot/db_practice.py", line 182, in save_phone_numbers
    host=host,
NameError: name 'host' is not defined
2024-05-18 11:51:28,471 - telegram.ext.dispatcher - ERROR - No error handlers are registered, logging exception.
Traceback (most recent call last):
  File "/usr/local/lib/python3.9/site-packages/telegram/ext/dispatcher.py", line 555, in process_update
    handler.handle_update(update, self, check, context)
  File "/usr/local/lib/python3.9/site-packages/telegram/ext/conversationhandler.py", line 626, in handle_update
    new_state = handler.handle_update(update, dispatcher, check_result, context)
  File "/usr/local/lib/python3.9/site-packages/telegram/ext/handler.py", line 198, in handle_update
    return self.callback(update, context)
  File "/bot/db_practice.py", line 182, in save_phone_numbers
    conn.close()
NameError: name 'host' is not defined
2024-05-18 11:51:37,428 - telegram.ext.updater - INFO - Received signal 15 (SIGTERM), stopping...
2024-05-18 11:51:37,429 - apscheduler.scheduler - INFO - Scheduler has been shut down
2024-05-18 11:51:43,033 - apscheduler.scheduler - INFO - Scheduler started
2024-05-18 11:52:36,463 - telegram.ext.updater - INFO - Received signal 15 (SIGTERM), stopping...
2024-05-18 11:52:36,463 - apscheduler.scheduler - INFO - Scheduler has been shut down
2024-05-18 12:03:31,761 - apscheduler.scheduler - INFO - Scheduler started
2024-05-18 12:06:11,838 - telegram.ext.updater - INFO - Received signal 15 (SIGTERM), stopping...
2024-05-18 12:06:11,838 - apscheduler.scheduler - INFO - Scheduler has been shut down
2024-05-18 12:06:51,510 - apscheduler.scheduler - INFO - Scheduler started
2024-05-18 12:16:50,227 - telegram.ext.updater - INFO - Received signal 15 (SIGTERM), stopping...
2024-05-18 12:16:50,227 - apscheduler.scheduler - INFO - Scheduler has been shut down
2024-05-18 12:17:29,157 - apscheduler.scheduler - INFO - Scheduler started
2024-05-18 12:19:41,062 - telegram.ext.updater - INFO - Received signal 15 (SIGTERM), stopping...
2024-05-18 12:19:41,063 - apscheduler.scheduler - INFO - Scheduler has been shut down
2024-05-18 12:21:22,601 - apscheduler.scheduler - INFO - Scheduler started
2024-05-18 12:23:16,393 - telegram.ext.updater - INFO - Received signal 15 (SIGTERM), stopping...
2024-05-18 12:23:16,393 - apscheduler.scheduler - INFO - Scheduler has been shut down
2024-05-18 12:23:19,615 - apscheduler.scheduler - INFO - Scheduler started
2024-05-18 12:25:24,516 - telegram.ext.updater - INFO - Received signal 15 (SIGTERM), stopping...
2024-05-18 12:25:24,516 - apscheduler.scheduler - INFO - Scheduler has been shut down
2024-05-18 12:33:11,877 - apscheduler.scheduler - INFO - Scheduler started
2024-05-18 12:34:42,589 - telegram.ext.updater - INFO - Received signal 15 (SIGTERM), stopping...
2024-05-18 12:34:42,590 - apscheduler.scheduler - INFO - Scheduler has been shut down
2024-05-18 12:35:14,459 - apscheduler.scheduler - INFO - Scheduler started
2024-05-18 12:39:21,336 - telegram.ext.updater - INFO - Received signal 15 (SIGTERM), stopping...
2024-05-18 12:39:21,337 - apscheduler.scheduler - INFO - Scheduler has been shut down
2024-05-18 12:39:31,591 - apscheduler.scheduler - INFO - Scheduler started
2024-05-18 12:39:42,195 - monitoring - INFO - /get_release command executed by
2024-05-18 12:41:56,468 - telegram.ext.dispatcher - ERROR - No error handlers are registered, logging exception.
Traceback (most recent call last):
  File "/usr/local/lib/python3.9/site-packages/telegram/ext/dispatcher.py", line 555, in process_update
    handler.handle_update(update, self, check, context)
  File "/usr/local/lib/python3.9/site-packages/telegram/ext/handler.py", line 198, in handle_update
    return self.callback(update, context)
  File "/bot/monitoring.py", line 46, in get_release
    response = execute_ssh_command(host, port, username, password, "cat /etc/*-release")
  File "/bot/monitoring.py", line 35, in execute_ssh_command
    client.connect(hostname=host, port=port, username=username, password=password)
  File "/usr/local/lib/python3.9/site-packages/paramiko/client.py", line 386, in connect
    sock.connect(addr)
TimeoutError: [Errno 110] Connection timed out
2024-05-18 12:42:27,085 - telegram.ext.updater - INFO - Received signal 15 (SIGTERM), stopping...
2024-05-18 12:42:27,085 - apscheduler.scheduler - INFO - Scheduler has been shut down
2024-05-18 12:43:48,850 - apscheduler.scheduler - INFO - Scheduler started
2024-05-18 12:44:08,658 - telegram.ext.updater - INFO - Received signal 15 (SIGTERM), stopping...
2024-05-18 12:44:08,658 - apscheduler.scheduler - INFO - Scheduler has been shut down
2024-05-18 12:44:12,680 - apscheduler.scheduler - INFO - Scheduler started
2024-05-18 12:44:21,141 - monitoring - INFO - /get_release command executed by
2024-05-18 12:44:24,301 - telegram.ext.dispatcher - ERROR - No error handlers are registered, logging exception.
Traceback (most recent call last):
  File "/usr/local/lib/python3.9/site-packages/telegram/ext/dispatcher.py", line 555, in process_update
    handler.handle_update(update, self, check, context)
  File "/usr/local/lib/python3.9/site-packages/telegram/ext/handler.py", line 198, in handle_update
    return self.callback(update, context)
  File "/bot/monitoring.py", line 46, in get_release
    response = execute_ssh_command(host, port, username, password, "cat /etc/*-release")
  File "/bot/monitoring.py", line 35, in execute_ssh_command
    client.connect(hostname=host, port=port, username=username, password=password)
  File "/usr/local/lib/python3.9/site-packages/paramiko/client.py", line 409, in connect
    raise NoValidConnectionsError(errors)
paramiko.ssh_exception.NoValidConnectionsError: [Errno None] Unable to connect to port 22 on 192.168.0.35
2024-05-18 12:48:15,185 - telegram.ext.updater - INFO - Received signal 15 (SIGTERM), stopping...
2024-05-18 12:48:15,186 - apscheduler.scheduler - INFO - Scheduler has been shut down
2024-05-18 12:49:04,682 - apscheduler.scheduler - INFO - Scheduler started
2024-05-18 12:53:14,636 - monitoring - INFO - /get_release command executed by
2024-05-18 12:53:17,794 - telegram.ext.dispatcher - ERROR - No error handlers are registered, logging exception.
Traceback (most recent call last):
  File "/usr/local/lib/python3.9/site-packages/telegram/ext/dispatcher.py", line 555, in process_update
    handler.handle_update(update, self, check, context)
  File "/usr/local/lib/python3.9/site-packages/telegram/ext/handler.py", line 198, in handle_update
    return self.callback(update, context)
  File "/bot/monitoring.py", line 46, in get_release
    response = execute_ssh_command(host, port, username, password, "cat /etc/*-release")
  File "/bot/monitoring.py", line 35, in execute_ssh_command
    client.connect(hostname=host, port=port, username=username, password=password)
  File "/usr/local/lib/python3.9/site-packages/paramiko/client.py", line 409, in connect
    raise NoValidConnectionsError(errors)
paramiko.ssh_exception.NoValidConnectionsError: [Errno None] Unable to connect to port 22 on 192.168.0.35
2024-05-18 12:53:22,456 - monitoring - INFO - /get_release command executed by
2024-05-18 12:53:25,554 - telegram.ext.dispatcher - ERROR - No error handlers are registered, logging exception.
Traceback (most recent call last):
  File "/usr/local/lib/python3.9/site-packages/telegram/ext/dispatcher.py", line 555, in process_update
    handler.handle_update(update, self, check, context)
  File "/usr/local/lib/python3.9/site-packages/telegram/ext/handler.py", line 198, in handle_update
    return self.callback(update, context)
  File "/bot/monitoring.py", line 46, in get_release
    response = execute_ssh_command(host, port, username, password, "cat /etc/*-release")
  File "/bot/monitoring.py", line 35, in execute_ssh_command
    client.connect(hostname=host, port=port, username=username, password=password)
  File "/usr/local/lib/python3.9/site-packages/paramiko/client.py", line 409, in connect
    raise NoValidConnectionsError(errors)
paramiko.ssh_exception.NoValidConnectionsError: [Errno None] Unable to connect to port 22 on 192.168.0.35
2024-05-18 12:53:57,903 - telegram.ext.updater - INFO - Received signal 15 (SIGTERM), stopping...
2024-05-18 12:53:57,903 - apscheduler.scheduler - INFO - Scheduler has been shut down
2024-05-18 12:54:04,819 - apscheduler.scheduler - INFO - Scheduler started
2024-05-18 12:54:28,110 - monitoring - INFO - /get_release command executed by
2024-05-18 12:55:19,190 - telegram.ext.updater - INFO - Received signal 15 (SIGTERM), stopping...
2024-05-18 12:55:19,191 - apscheduler.scheduler - INFO - Scheduler has been shut down
2024-05-18 13:18:59,458 - apscheduler.scheduler - INFO - Scheduler started
2024-05-18 13:19:23,162 - monitoring - INFO - /get_release command executed by
2024-05-18 13:19:23,308 - paramiko.transport - INFO - Connected (version 2.0, client OpenSSH_9.6p1)
2024-05-18 13:19:23,459 - paramiko.transport - INFO - Authentication (password) successful!
2024-05-18 13:20:34,876 - telegram.ext.dispatcher - ERROR - No error handlers are registered, logging exception.
Traceback (most recent call last):
  File "/usr/local/lib/python3.9/site-packages/telegram/ext/dispatcher.py", line 555, in process_update
    handler.handle_update(update, self, check, context)
  File "/usr/local/lib/python3.9/site-packages/telegram/ext/handler.py", line 198, in handle_update
    return self.callback(update, context)
  File "/bot/db_practice.py", line 98, in get_emails
    response = execute_sql_command(host, db_port, dbname, username, password, "SELECT * FROM emails;")
NameError: name 'dbname' is not defined
2024-05-18 13:20:50,200 - telegram.ext.dispatcher - ERROR - No error handlers are registered, logging exception.
Traceback (most recent call last):
  File "/usr/local/lib/python3.9/site-packages/telegram/ext/dispatcher.py", line 555, in process_update
    handler.handle_update(update, self, check, context)
  File "/usr/local/lib/python3.9/site-packages/telegram/ext/handler.py", line 198, in handle_update
    return self.callback(update, context)
  File "/bot/db_practice.py", line 103, in get_phones
    response = execute_sql_command(host, db_port, dbname, username, password, "SELECT * FROM phones;")
NameError: name 'dbname' is not defined
2024-05-18 13:21:45,131 - telegram.ext.dispatcher - ERROR - No error handlers are registered, logging exception.
Traceback (most recent call last):
  File "/usr/local/lib/python3.9/site-packages/telegram/ext/dispatcher.py", line 555, in process_update
    handler.handle_update(update, self, check, context)
  File "/usr/local/lib/python3.9/site-packages/telegram/ext/handler.py", line 198, in handle_update
    return self.callback(update, context)
  File "/bot/db_practice.py", line 93, in get_replica
    response = execute_sql_command(host, db_port, dbname, username, password, "SELECT * FROM pg_catalog.pg_log ORDER BY log_time DESC LIMIT 35;")
NameError: name 'dbname' is not defined
2024-05-18 13:21:46,956 - telegram.ext.dispatcher - ERROR - No error handlers are registered, logging exception.
Traceback (most recent call last):
  File "/usr/local/lib/python3.9/site-packages/telegram/ext/dispatcher.py", line 555, in process_update
    handler.handle_update(update, self, check, context)
  File "/usr/local/lib/python3.9/site-packages/telegram/ext/handler.py", line 198, in handle_update
    return self.callback(update, context)
  File "/bot/db_practice.py", line 93, in get_replica
    response = execute_sql_command(host, db_port, dbname, username, password, "SELECT * FROM pg_catalog.pg_log ORDER BY log_time DESC LIMIT 35;")
NameError: name 'dbname' is not defined
2024-05-18 13:21:54,455 - telegram.ext.dispatcher - ERROR - No error handlers are registered, logging exception.
Traceback (most recent call last):
  File "/usr/local/lib/python3.9/site-packages/telegram/ext/dispatcher.py", line 555, in process_update
    handler.handle_update(update, self, check, context)
  File "/usr/local/lib/python3.9/site-packages/telegram/ext/handler.py", line 198, in handle_update
    return self.callback(update, context)
  File "/bot/db_practice.py", line 93, in get_replica
    response = execute_sql_command(host, db_port, dbname, username, password, "SELECT * FROM pg_catalog.pg_log ORDER BY log_time DESC LIMIT 35;")
NameError: name 'dbname' is not defined
2024-05-18 13:22:10,807 - telegram.ext.dispatcher - ERROR - No error handlers are registered, logging exception.
Traceback (most recent call last):
  File "/usr/local/lib/python3.9/site-packages/telegram/ext/dispatcher.py", line 555, in process_update
    handler.handle_update(update, self, check, context)
  File "/usr/local/lib/python3.9/site-packages/telegram/ext/handler.py", line 198, in handle_update
    return self.callback(update, context)
  File "/bot/db_practice.py", line 98, in get_emails
    response = execute_sql_command(host, db_port, dbname, username, password, "SELECT * FROM emails;")
NameError: name 'dbname' is not defined
2024-05-18 13:22:11,975 - telegram.ext.dispatcher - ERROR - No error handlers are registered, logging exception.
Traceback (most recent call last):
  File "/usr/local/lib/python3.9/site-packages/telegram/ext/dispatcher.py", line 555, in process_update
    handler.handle_update(update, self, check, context)
  File "/usr/local/lib/python3.9/site-packages/telegram/ext/handler.py", line 198, in handle_update
    return self.callback(update, context)
  File "/bot/db_practice.py", line 103, in get_phones
    response = execute_sql_command(host, db_port, dbname, username, password, "SELECT * FROM phones;")
NameError: name 'dbname' is not defined
2024-05-18 13:23:12,490 - monitoring - INFO - /get_release command executed by
2024-05-18 13:23:12,507 - paramiko.transport - INFO - Connected (version 2.0, client OpenSSH_9.6p1)
2024-05-18 13:23:12,578 - paramiko.transport - INFO - Authentication (password) successful!
2024-05-18 13:35:03,636 - telegram.ext.updater - INFO - Received signal 15 (SIGTERM), stopping...
2024-05-18 13:35:03,637 - apscheduler.scheduler - INFO - Scheduler has been shut down
2024-05-18 13:37:10,202 - apscheduler.scheduler - INFO - Scheduler started
2024-05-18 13:37:24,425 - monitoring - INFO - /get_release command executed by
2024-05-18 13:37:24,443 - paramiko.transport - INFO - Connected (version 2.0, client OpenSSH_9.6p1)
2024-05-18 13:37:24,513 - paramiko.transport - INFO - Authentication (password) successful!
2024-05-18 13:37:26,838 - paramiko.transport - INFO - Connected (version 2.0, client OpenSSH_9.6p1)
2024-05-18 13:37:26,908 - paramiko.transport - INFO - Authentication (password) successful!
2024-05-18 13:37:30,548 - paramiko.transport - INFO - Connected (version 2.0, client OpenSSH_9.6p1)
2024-05-18 13:37:30,620 - paramiko.transport - INFO - Authentication (password) successful!
2024-05-18 13:37:33,517 - telegram.ext.dispatcher - ERROR - No error handlers are registered, logging exception.
Traceback (most recent call last):
  File "/usr/local/lib/python3.9/site-packages/telegram/ext/dispatcher.py", line 555, in process_update
    handler.handle_update(update, self, check, context)
  File "/usr/local/lib/python3.9/site-packages/telegram/ext/handler.py", line 198, in handle_update
    return self.callback(update, context)
  File "/bot/db_practice.py", line 99, in get_emails
    response = execute_sql_command(host, db_port, dbname, username, password, "SELECT * FROM emails;")
NameError: name 'dbname' is not defined
2024-05-18 13:37:38,220 - telegram.ext.dispatcher - ERROR - No error handlers are registered, logging exception.
Traceback (most recent call last):
  File "/usr/local/lib/python3.9/site-packages/telegram/ext/dispatcher.py", line 555, in process_update
    handler.handle_update(update, self, check, context)
  File "/usr/local/lib/python3.9/site-packages/telegram/ext/handler.py", line 198, in handle_update
    return self.callback(update, context)
  File "/bot/db_practice.py", line 104, in get_phones
    response = execute_sql_command(host, db_port, dbname, username, password, "SELECT * FROM phones;")
NameError: name 'dbname' is not defined
2024-05-18 13:37:53,277 - telegram.ext.dispatcher - ERROR - No error handlers are registered, logging exception.
Traceback (most recent call last):
  File "/usr/local/lib/python3.9/site-packages/telegram/ext/dispatcher.py", line 555, in process_update
    handler.handle_update(update, self, check, context)
  File "/usr/local/lib/python3.9/site-packages/telegram/ext/handler.py", line 198, in handle_update
    return self.callback(update, context)
  File "/bot/db_practice.py", line 94, in get_replica
    response = execute_sql_command(host, db_port, dbname, username, password, "SELECT * FROM pg_catalog.pg_log ORDER BY log_time DESC LIMIT 35;")
NameError: name 'dbname' is not defined
2024-05-18 13:40:06,455 - telegram.ext.updater - INFO - Received signal 15 (SIGTERM), stopping...
2024-05-18 13:40:06,455 - apscheduler.scheduler - INFO - Scheduler has been shut down
2024-05-18 13:40:26,763 - apscheduler.scheduler - INFO - Scheduler started
2024-05-18 13:52:06,359 - telegram.ext.updater - INFO - Received signal 15 (SIGTERM), stopping...
2024-05-18 13:52:06,360 - apscheduler.scheduler - INFO - Scheduler has been shut down
2024-05-18 14:10:33,684 - apscheduler.scheduler - INFO - Scheduler started
2024-05-18 14:12:03,094 - monitoring - INFO - /get_release command executed by
2024-05-18 14:12:03,228 - paramiko.transport - INFO - Connected (version 2.0, client OpenSSH_9.6p1)
2024-05-18 14:12:03,496 - paramiko.transport - INFO - Authentication (password) successful!
2024-05-18 14:12:06,536 - paramiko.transport - INFO - Connected (version 2.0, client OpenSSH_9.6p1)
2024-05-18 14:12:06,607 - paramiko.transport - INFO - Authentication (password) successful!
2024-05-18 14:39:25,748 - telegram.ext.updater - INFO - Received signal 15 (SIGTERM), stopping...
2024-05-18 14:39:25,750 - apscheduler.scheduler - INFO - Scheduler has been shut down
2024-05-18 14:40:46,987 - apscheduler.scheduler - INFO - Scheduler started
2024-05-18 14:45:53,013 - telegram.ext.updater - INFO - Received signal 15 (SIGTERM), stopping...
2024-05-18 14:45:53,013 - apscheduler.scheduler - INFO - Scheduler has been shut down
2024-05-18 14:46:07,985 - apscheduler.scheduler - INFO - Scheduler started
2024-05-18 14:52:40,762 - telegram.ext.updater - INFO - Received signal 15 (SIGTERM), stopping...
2024-05-18 14:52:40,763 - apscheduler.scheduler - INFO - Scheduler has been shut down
2024-05-18 14:53:12,014 - apscheduler.scheduler - INFO - Scheduler started
2024-05-18 14:53:18,878 - telegram.ext.updater - INFO - Received signal 15 (SIGTERM), stopping...
2024-05-18 14:53:18,879 - apscheduler.scheduler - INFO - Scheduler has been shut down
2024-05-18 14:53:58,224 - apscheduler.scheduler - INFO - Scheduler started
2024-05-18 14:55:11,884 - telegram.ext.updater - INFO - Received signal 15 (SIGTERM), stopping...
2024-05-18 14:55:11,884 - apscheduler.scheduler - INFO - Scheduler has been shut down
2024-05-18 14:56:19,071 - apscheduler.scheduler - INFO - Scheduler started
2024-05-18 14:56:45,125 - telegram.ext.updater - INFO - Received signal 15 (SIGTERM), stopping...
2024-05-18 14:56:45,125 - apscheduler.scheduler - INFO - Scheduler has been shut down
2024-05-18 14:57:36,884 - apscheduler.scheduler - INFO - Scheduler started
2024-05-18 14:58:54,582 - telegram.ext.updater - INFO - Received signal 15 (SIGTERM), stopping...
2024-05-18 14:58:54,583 - apscheduler.scheduler - INFO - Scheduler has been shut down
2024-05-18 14:59:02,038 - apscheduler.scheduler - INFO - Scheduler started
2024-05-18 14:59:12,919 - telegram.ext.updater - INFO - Received signal 15 (SIGTERM), stopping...
2024-05-18 14:59:12,920 - apscheduler.scheduler - INFO - Scheduler has been shut down
2024-05-18 14:59:16,181 - telegram.ext.updater - WARNING - Exiting immediately!
2024-05-18 15:00:35,202 - apscheduler.scheduler - INFO - Scheduler started
2024-05-18 15:01:54,777 - paramiko.transport - INFO - Connected (version 2.0, client OpenSSH_9.6p1)
2024-05-18 15:01:55,047 - paramiko.transport - INFO - Authentication (password) successful!
2024-05-18 15:02:04,539 - monitoring - INFO - /get_release command executed by
2024-05-18 15:02:04,558 - paramiko.transport - INFO - Connected (version 2.0, client OpenSSH_9.6p1)
2024-05-18 15:02:04,633 - paramiko.transport - INFO - Authentication (password) successful!
2024-05-18 15:04:37,409 - telegram.ext.updater - INFO - Received signal 15 (SIGTERM), stopping...
2024-05-18 15:04:37,410 - apscheduler.scheduler - INFO - Scheduler has been shut down
2024-05-19 05:58:03,384 - apscheduler.scheduler - INFO - Scheduler started
2024-05-19 05:59:54,181 - telegram.ext.updater - INFO - Received signal 15 (SIGTERM), stopping...
2024-05-19 05:59:54,182 - apscheduler.scheduler - INFO - Scheduler has been shut down
2024-05-19 06:00:01,960 - apscheduler.scheduler - INFO - Scheduler started
2024-05-19 06:00:20,978 - telegram.ext.updater - INFO - Received signal 15 (SIGTERM), stopping...
2024-05-19 06:00:20,978 - apscheduler.scheduler - INFO - Scheduler has been shut down
2024-05-19 07:47:38,654 - apscheduler.scheduler - INFO - Scheduler started
2024-05-19 07:48:07,417 - telegram.ext.updater - INFO - Received signal 15 (SIGTERM), stopping...
2024-05-19 07:48:07,417 - apscheduler.scheduler - INFO - Scheduler has been shut down
2024-05-19 10:08:29,306 - apscheduler.scheduler - INFO - Scheduler started
2024-05-19 10:08:52,092 - telegram.ext.updater - INFO - Received signal 15 (SIGTERM), stopping...
2024-05-19 10:08:52,099 - apscheduler.scheduler - INFO - Scheduler has been shut down
2024-05-19 10:14:22,160 - apscheduler.scheduler - INFO - Scheduler started
2024-05-19 10:14:41,319 - telegram.ext.updater - INFO - Received signal 15 (SIGTERM), stopping...
2024-05-19 10:14:41,320 - apscheduler.scheduler - INFO - Scheduler has been shut down
2024-05-19 10:36:19,293 - apscheduler.scheduler - INFO - Scheduler started
2024-05-19 10:36:40,648 - telegram.ext.updater - INFO - Received signal 15 (SIGTERM), stopping...
2024-05-19 10:36:40,650 - apscheduler.scheduler - INFO - Scheduler has been shut down
